Workbook

Sheet 曾庆伟
A1: 日期 | B1: 出勤工时 | C1: 工时效率 | D1: 项目号 | E1: 产品型号 | F1: 长度（mm） | G1: 工序 | H1: 单件标准工时（S/支） | I1: 合格产量（支数） | J1: 合格工时（S） | K1: 个人不良产量（支数） | L1: 加分项 | M1: 减分项 | N1: 考核合计工时（秒） | O1: 合计（小时） | P1: 说明 | Q1: 备注
J2: =H2*I2 -> 0 | N2: =J2-M2+L2 -> 0 | O2: =N2/3600 -> 0
A3: 46083 | B3: 11 | C3: =SUM(O3:O4)/B3 -> 1.3757576 | D3: 25090907-01 | E3: 113-80 | F3: 1942 | G3: 刮毛刺 | H3: {=INDEX(成本核算表!J:J,MATCH(1,(成本核算表!D:D=E3)*(成本核算表!C:C=G3),0))} -> 48 | I3: 507 | J3: =H3*I3 -> 24336 | N3: =J3-M3+L3 -> 24336 | O3: =N3/3600 -> 6.76
A4: 46083 | D4: 25090907-02 | E4: 113-80 | F4: 1942 | G4: 刮毛刺 | H4: {=INDEX(成本核算表!J:J,MATCH(1,(成本核算表!D:D=E4)*(成本核算表!C:C=G4),0))} -> 48 | I4: 628 | J4: =H4*I4 -> 30144 | N4: =J4-M4+L4 -> 30144 | O4: =N4/3600 -> 8.3733333
A5: 46084 | B5: 11 | C5: =SUM(O5:O8)/B5 -> 1.3065657 | E5: 导电杆 | G5: CNC | H5: {=INDEX(成本核算表!J:J,MATCH(1,(成本核算表!D:D=E5)*(成本核算表!C:C=G5),0))} -> 300 | I5: 104 | J5: =H5*I5 -> 31200 | N5: =J5-M5+L5 -> 31200 | O5: =N5/3600 -> 8.6666667
A6: 46084 | E6: 门小件 | G6: CNC1 | H6: {=INDEX(成本核算表!J:J,MATCH(1,(成本核算表!D:D=E6)*(成本核算表!C:C=G6),0))} -> 450 | I6: 18 | J6: =H6*I6 -> 8100 | N6: =J6-M6+L6 -> 8100 | O6: =N6/3600 -> 2.25
A7: 46084 | E7: 门小件 | G7: CNC2 | H7: {=INDEX(成本核算表!J:J,MATCH(1,(成本核算表!D:D=E7)*(成本核算表!C:C=G7),0))} -> 120 | I7: 17 | J7: =H7*I7 -> 2040 | N7: =J7-M7+L7 -> 2040 | O7: =N7/3600 -> 0.56666667
A8: 46084 | D8: 26022505-03 | E8: 258-308 | F8: 180 | G8: CNC1 | H8: {=INDEX(成本核算表!J:J,MATCH(1,(成本核算表!D:D=E8)*(成本核算表!C:C=G8),0))} -> 800 | I8: 13 | J8: =H8*I8 -> 10400 | N8: =J8-M8+L8 -> 10400 | O8: =N8/3600 -> 2.8888889
A9: 46085 | B9: 11 | C9: =SUM(O9:O11)/B9 -> 0.83151515 | E9: 门小件 | G9: CNC3 | H9: {=INDEX(成本核算表!J:J,MATCH(1,(成本核算表!D:D=E9)*(成本核算表!C:C=G9),0))} -> 120 | I9: 18 | J9: =H9*I9 -> 2160 | N9: =J9-M9+L9 -> 2160 | O9: =N9/3600 -> 0.6
A10: 46085 | E10: 导电杆 | G10: CNC | H10: 42 | I10: 104 | J10: =H10*I10 -> 4368 | N10: =J10-M10+L10 -> 4368 | O10: =N10/3600 -> 1.2133333
A11: 46085 | D11: 26022505-02 | E11: 258-308 | F11: 180 | G11: CNC1 | H11: {=INDEX(成本核算表!J:J,MATCH(1,(成本核算表!D:D=E11)*(成本核算表!C:C=G11),0))} -> 800 | I11: 33 | J11: =H11*I11 -> 26400 | N11: =J11-M11+L11 -> 26400 | O11: =N11/3600 -> 7.3333333
A12: 46086 | B12: 11 | C12: =SUM(O12:O13)/B12 -> 0.72979798 | D12: 26022505-02 | E12: 258-308 | F12: 180 | G12: CNC1 | H12: {=INDEX(成本核算表!J:J,MATCH(1,(成本核算表!D:D=E12)*(成本核算表!C:C=G12),0))} -> 800 | I12: 8 | J12: =H12*I12 -> 6400 | N12: =J12-M12+L12 -> 6400 | O12: =N12/3600 -> 1.7777778
A13: 46086 | D13: 26022505-02 | E13: 258-308 | F13: 180 | G13: 检验 | H13: {=INDEX(成本核算表!J:J,MATCH(1,(成本核算表!D:D=E13)*(成本核算表!C:C=G13),0))} -> 60 | I13: 135 | J13: =H13*I13 -> 8100 | L13: 14400 | N13: =J13-M13+L13 -> 22500 | O13: =N13/3600 -> 6.25 | Q13: 来料表面不好，检验
A14: 46087 | B14: 11 | C14: =SUM(O14:O16)/B14 -> 0.95454545 | E14: 286-424 | G14: 打孔 | H14: {=INDEX(成本核算表!J:J,MATCH(1,(成本核算表!D:D=E14)*(成本核算表!C:C=G14),0))} -> 100 | I14: 18 | J14: =H14*I14 -> 1800 | N14: =J14-M14+L14 -> 1800 | O14: =N14/3600 -> 0.5
A15: 46087 | E15: 286-337 | G15: 打孔 | H15: {=INDEX(成本核算表!J:J,MATCH(1,(成本核算表!D:D=E15)*(成本核算表!C:C=G15),0))} -> 100 | I15: 12 | J15: =H15*I15 -> 1200 | N15: =J15-M15+L15 -> 1200 | O15: =N15/3600 -> 0.33333333
A16: 46087 | D16: 26020502-03 | E16: 105-331 | F16: 119.5 | G16: 倒角 | H16: {=INDEX(成本核算表!J:J,MATCH(1,(成本核算表!D:D=E16)*(成本核算表!C:C=G16),0))} -> 15 | I16: 400 | J16: =H16*I16 -> 6000 | L16: =3600*8 -> 28800 | N16: =J16-M16+L16 -> 34800 | O16: =N16/3600 -> 9.6666667
A17: 46088 | B17: 4 | C17: =O17/B17 -> 0.78958333 | E17: 286-430 | G17: 铣缺口 | H17: 30 | I17: 19 | J17: =H17*I17 -> 570 | L17: =3*3600 -> 10800 | N17: =J17-M17+L17 -> 11370 | O17: =N17/3600 -> 3.1583333
H18: {=INDEX(成本核算表!J:J,MATCH(1,(成本核算表!D:D=E18)*(成本核算表!C:C=G18),0))} -> 0 | J18: =H18*I18 -> 0 | N18: =J18-M18+L18 -> 0 | O18: =N18/3600 -> 0
A19: 46090 | B19: 11 | C19: =O19/B19 -> 0.42424242 | D19: 26020502-02 | E19: 105-331 | F19: 119.5 | G19: 沉孔 | H19: {=INDEX(成本核算表!J:J,MATCH(1,(成本核算表!D:D=E19)*(成本核算表!C:C=G19),0))} -> 12 | I19: 1400 | J19: =H19*I19 -> 16800 | N19: =J19-M19+L19 -> 16800 | O19: =N19/3600 -> 4.6666667
A20: 46091 | B20: 11 | C20: =O20/B20 -> 0.46363636 | D20: 26020502-02 | E20: 105-331 | F20: 119.5 | G20: 沉孔 | H20: {=INDEX(成本核算表!J:J,MATCH(1,(成本核算表!D:D=E20)*(成本核算表!C:C=G20),0))} -> 12 | I20: 1530 | J20: =H20*I20 -> 18360 | N20: =J20-M20+L20 -> 18360 | O20: =N20/3600 -> 5.1
A21: 46092 | B21: 11 | H21: {=INDEX(成本核算表!J:J,MATCH(1,(成本核算表!D:D=E21)*(成本核算表!C:C=G21),0))} -> 0 | J21: =H21*I21 -> 0 | L21: =11*3600 -> 39600 | N21: =J21-M21+L21 -> 39600 | O21: =N21/3600 -> 11
A22: 46093 | B22: 11 | C22: =O22/B22 -> 0.36363636 | D22: 26020502-02 | E22: 105-331 | F22: 119.5 | G22: 沉孔 | H22: {=INDEX(成本核算表!J:J,MATCH(1,(成本核算表!D:D=E22)*(成本核算表!C:C=G22),0))} -> 12 | I22: =120+1080 -> 1200 | J22: =H22*I22 -> 14400 | N22: =J22-M22+L22 -> 14400 | O22: =N22/3600 -> 4
A23: 46094 | B23: 11 | C23: =O23/B23 -> 0.57575758 | D23: 26020502-02 | E23: 105-331 | F23: 119.5 | G23: 沉孔 | H23: {=INDEX(成本核算表!J:J,MATCH(1,(成本核算表!D:D=E23)*(成本核算表!C:C=G23),0))} -> 12 | I23: 1900 | J23: =H23*I23 -> 22800 | N23: =J23-M23+L23 -> 22800 | O23: =N23/3600 -> 6.3333333
A24: 46095 | B24: 9.5 | C24: =O24/B24 -> 0.43754386 | D24: 26020502-02 | E24: 105-331 | F24: 119.5 | G24: 沉孔 | H24: {=INDEX(成本核算表!J:J,MATCH(1,(成本核算表!D:D=E24)*(成本核算表!C:C=G24),0))} -> 12 | I24: 1247 | J24: =H24*I24 -> 14964 | N24: =J24-M24+L24 -> 14964 | O24: =N24/3600 -> 4.1566667
H25: {=INDEX(成本核算表!J:J,MATCH(1,(成本核算表!D:D=E25)*(成本核算表!C:C=G25),0))} -> 0 | J25: =H25*I25 -> 0 | N25: =J25-M25+L25 -> 0 | O25: =N25/3600 -> 0
A26: 46097 | B26: 11 | C26: =SUM(O26:O27)/B26 -> 0.81090909 | D26: 26020502-03 | E26: 105-331 | F26: 119.5 | G26: 倒角 | H26: {=INDEX(成本核算表!J:J,MATCH(1,(成本核算表!D:D=E26)*(成本核算表!C:C=G26),0))} -> 15 | I26: 504 | J26: =H26*I26 -> 7560 | N26: =J26-M26+L26 -> 7560 | O26: =N26/3600 -> 2.1
A27: 46097 | D27: 26020502-02 | E27: 105-331 | F27: 119.5 | G27: 沉孔 | H27: {=INDEX(成本核算表!J:J,MATCH(1,(成本核算表!D:D=E27)*(成本核算表!C:C=G27),0))} -> 12 | I27: 2046 | J27: =H27*I27 -> 24552 | N27: =J27-M27+L27 -> 24552 | O27: =N27/3600 -> 6.82
A28: 46098 | B28: 11 | C28: =SUM(O28:O29)/B28 -> 0.63636364 | D28: 26020502-03 | E28: 105-331 | F28: 119.5 | G28: 倒角 | H28: {=INDEX(成本核算表!J:J,MATCH(1,(成本核算表!D:D=E28)*(成本核算表!C:C=G28),0))} -> 15 | I28: 1232 | J28: =H28*I28 -> 18480 | N28: =J28-M28+L28 -> 18480 | O28: =N28/3600 -> 5.1333333
A29: 46098 | D29: 26020502-02 | E29: 105-331 | F29: 119.5 | G29: 沉孔 | H29: {=INDEX(成本核算表!J:J,MATCH(1,(成本核算表!D:D=E29)*(成本核算表!C:C=G29),0))} -> 12 | I29: 560 | J29: =H29*I29 -> 6720 | N29: =J29-M29+L29 -> 6720 | O29: =N29/3600 -> 1.8666667
A30: 46099 | B30: 11 | C30: =O30/B30 -> 0.75 | D30: 26020502-02 | E30: 105-331 | F30: 119.5 | G30: 倒角 | H30: {=INDEX(成本核算表!J:J,MATCH(1,(成本核算表!D:D=E30)*(成本核算表!C:C=G30),0))} -> 15 | I30: =850+1130 -> 1980 | J30: =H30*I30 -> 29700 | N30: =J30-M30+L30 -> 29700 | O30: =N30/3600 -> 8.25
A31: 46100 | B31: 11 | C31: =O31/B31 -> 0.57575758 | D31: 26020502-03 | E31: 105-331 | F31: 119.5 | G31: 倒角 | H31: {=INDEX(成本核算表!J:J,MATCH(1,(成本核算表!D:D=E31)*(成本核算表!C:C=G31),0))} -> 15 | I31: 1520 | J31: =H31*I31 -> 22800 | N31: =J31-M31+L31 -> 22800 | O31: =N31/3600 -> 6.3333333
A32: 46101 | B32: 11 | C32: =O32/B32 -> 0.83712121 | D32: 26020502-03 | E32: 105-331 | F32: 119.5 | G32: 倒角 | H32: {=INDEX(成本核算表!J:J,MATCH(1,(成本核算表!D:D=E32)*(成本核算表!C:C=G32),0))} -> 15 | I32: 650 | J32: =H32*I32 -> 9750 | L32: =6.5*3600 -> 23400 | N32: =J32-M32+L32 -> 33150 | O32: =N32/3600 -> 9.2083333
H33: {=INDEX(成本核算表!J:J,MATCH(1,(成本核算表!D:D=E33)*(成本核算表!C:C=G33),0))} -> 0 | J33: =H33*I33 -> 0 | N33: =J33-M33+L33 -> 0 | O33: =N33/3600 -> 0
H34: {=INDEX(成本核算表!J:J,MATCH(1,(成本核算表!D:D=E34)*(成本核算表!C:C=G34),0))} -> 0 | J34: =H34*I34 -> 0 | N34: =J34-M34+L34 -> 0 | O34: =N34/3600 -> 0
H35: {=INDEX(成本核算表!J:J,MATCH(1,(成本核算表!D:D=E35)*(成本核算表!C:C=G35),0))} -> 0 | J35: =H35*I35 -> 0 | N35: =J35-M35+L35 -> 0 | O35: =N35/3600 -> 0
H36: {=INDEX(成本核算表!J:J,MATCH(1,(成本核算表!D:D=E36)*(成本核算表!C:C=G36),0))} -> 0 | J36: =H36*I36 -> 0 | N36: =J36-M36+L36 -> 0 | O36: =N36/3600 -> 0
H37: {=INDEX(成本核算表!J:J,MATCH(1,(成本核算表!D:D=E37)*(成本核算表!C:C=G37),0))} -> 0 | J37: =H37*I37 -> 0 | N37: =J37-M37+L37 -> 0 | O37: =N37/3600 -> 0
H38: {=INDEX(成本核算表!J:J,MATCH(1,(成本核算表!D:D=E38)*(成本核算表!C:C=G38),0))} -> 0 | J38: =H38*I38 -> 0 | N38: =J38-M38+L38 -> 0 | O38: =N38/3600 -> 0
H39: {=INDEX(成本核算表!J:J,MATCH(1,(成本核算表!D:D=E39)*(成本核算表!C:C=G39),0))} -> 0 | J39: =H39*I39 -> 0 | N39: =J39-M39+L39 -> 0 | O39: =N39/3600 -> 0
H40: {=INDEX(成本核算表!J:J,MATCH(1,(成本核算表!D:D=E40)*(成本核算表!C:C=G40),0))} -> 0 | J40: =H40*I40 -> 0 | N40: =J40-M40+L40 -> 0 | O40: =N40/3600 -> 0
...

Sheet 王福雪
A1: 日期 | B1: 出勤工时 | C1: 工时效率 | D1: 项目号 | E1: 产品型号 | F1: 长度（mm） | G1: 工序 | H1: 单件标准工时（S/支） | I1: 合格产量（支数） | J1: 合格工时（S） | K1: 个人不良产量（支数） | L1: 加分项 | M1: 减分项 | N1: 考核合计工时（秒） | O1: 合计（小时） | P1: 说明 | Q1: 备注
A2: 46082 | B2: 9.5 | C2: =SUM(O2:O3)/B2 -> 1.3397661 | D2: 26010702-01 | E2: 286-474 | F2: 151.1 | G2: 冲孔 | H2: {=INDEX(成本核算表!J:J,MATCH(1,(成本核算表!D:D=E2)*(成本核算表!C:C=G2),0))} -> 20 | I2: 1400 | J2: =H2*I2 -> 28000 | N2: =J2-M2+L2 -> 28000 | O2: =N2/3600 -> 7.7777778
A3: 46082 | D3: 26010702-05 | E3: 286-470 | F3: 156 | G3: 冲孔 | H3: {=INDEX(成本核算表!J:J,MATCH(1,(成本核算表!D:D=E3)*(成本核算表!C:C=G3),0))} -> 15 | I3: 1188 | J3: =H3*I3 -> 17820 | N3: =J3-M3+L3 -> 17820 | O3: =N3/3600 -> 4.95
J4: =H4*I4 -> 0 | N4: =J4-M4+L4 -> 0 | O4: =N4/3600 -> 0
J5: =H5*I5 -> 0 | N5: =J5-M5+L5 -> 0 | O5: =N5/3600 -> 0
J6: =H6*I6 -> 0 | N6: =J6-M6+L6 -> 0 | O6: =N6/3600 -> 0
J7: =H7*I7 -> 0 | N7: =J7-M7+L7 -> 0 | O7: =N7/3600 -> 0
A8: 46087 | B8: 11 | C8: =SUM(O8:O9)/B8 -> 1.1893939 | D8: 26022709-02 | E8: 180-261 | F8: 950 | G8: 冲安装孔 | H8: {=INDEX(成本核算表!J:J,MATCH(1,(成本核算表!D:D=E8)*(成本核算表!C:C=G8),0))} -> 25 | I8: 1080 | J8: =H8*I8 -> 27000 | N8: =J8-M8+L8 -> 27000 | O8: =N8/3600 -> 7.5
A9: 46087 | D9: 26022711-02 | E9: 180-261 | F9: 950 | G9: 冲安装孔 | H9: {=INDEX(成本核算表!J:J,MATCH(1,(成本核算表!D:D=E9)*(成本核算表!C:C=G9),0))} -> 25 | I9: 804 | J9: =H9*I9 -> 20100 | N9: =J9-M9+L9 -> 20100 | O9: =N9/3600 -> 5.5833333
A10: 46088 | B10: 4 | C10: =SUM(O10:O10)/B10 -> 1.4288194 | D10: 26022711-01 | E10: 180-260 | F10: 950 | G10: 冲安装孔 | H10: {=INDEX(成本核算表!J:J,MATCH(1,(成本核算表!D:D=E10)*(成本核算表!C:C=G10),0))} -> 25 | I10: 823 | J10: =H10*I10 -> 20575 | N10: =J10-M10+L10 -> 20575 | O10: =N10/3600 -> 5.7152778
H11: {=INDEX(成本核算表!J:J,MATCH(1,(成本核算表!D:D=E11)*(成本核算表!C:C=G11),0))} -> 0 | J11: =H11*I11 -> 0 | N11: =J11-M11+L11 -> 0 | O11: =N11/3600 -> 0
H12: {=INDEX(成本核算表!J:J,MATCH(1,(成本核算表!D:D=E12)*(成本核算表!C:C=G12),0))} -> 0 | J12: =H12*I12 -> 0 | N12: =J12-M12+L12 -> 0 | O12: =N12/3600 -> 0
H13: {=INDEX(成本核算表!J:J,MATCH(1,(成本核算表!D:D=E13)*(成本核算表!C:C=G13),0))} -> 0 | J13: =H13*I13 -> 0 | N13: =J13-M13+L13 -> 0 | O13: =N13/3600 -> 0
H14: {=INDEX(成本核算表!J:J,MATCH(1,(成本核算表!D:D=E14)*(成本核算表!C:C=G14),0))} -> 0 | J14: =H14*I14 -> 0 | N14: =J14-M14+L14 -> 0 | O14: =N14/3600 -> 0
H15: {=INDEX(成本核算表!J:J,MATCH(1,(成本核算表!D:D=E15)*(成本核算表!C:C=G15),0))} -> 0 | J15: =H15*I15 -> 0 | N15: =J15-M15+L15 -> 0 | O15: =N15/3600 -> 0
H16: {=INDEX(成本核算表!J:J,MATCH(1,(成本核算表!D:D=E16)*(成本核算表!C:C=G16),0))} -> 0 | J16: =H16*I16 -> 0 | N16: =J16-M16+L16 -> 0 | O16: =N16/3600 -> 0
H17: {=INDEX(成本核算表!J:J,MATCH(1,(成本核算表!D:D=E17)*(成本核算表!C:C=G17),0))} -> 0 | J17: =H17*I17 -> 0 | N17: =J17-M17+L17 -> 0 | O17: =N17/3600 -> 0
H18: {=INDEX(成本核算表!J:J,MATCH(1,(成本核算表!D:D=E18)*(成本核算表!C:C=G18),0))} -> 0 | J18: =H18*I18 -> 0 | N18: =J18-M18+L18 -> 0 | O18: =N18/3600 -> 0
H19: {=INDEX(成本核算表!J:J,MATCH(1,(成本核算表!D:D=E19)*(成本核算表!C:C=G19),0))} -> 0 | J19: =H19*I19 -> 0 | N19: =J19-M19+L19 -> 0 | O19: =N19/3600 -> 0
H20: {=INDEX(成本核算表!J:J,MATCH(1,(成本核算表!D:D=E20)*(成本核算表!C:C=G20),0))} -> 0 | J20: =H20*I20 -> 0 | N20: =J20-M20+L20 -> 0 | O20: =N20/3600 -> 0
A21: 46099 | B21: 11 | C21: =SUM(O21:O22)/B21 -> 1.3145455 | D21: 26020502-03 | E21: 105-331 | F21: 119.5 | G21: 冲弯 | H21: {=INDEX(成本核算表!J:J,MATCH(1,(成本核算表!D:D=E21)*(成本核算表!C:C=G21),0))} -> 12 | I21: 3528 | J21: =H21*I21 -> 42336 | N21: =J21-M21+L21 -> 42336 | O21: =N21/3600 -> 11.76
A22: 46099 | D22: 26020502-02 | E22: 105-331 | F22: 119.5 | G22: 冲弯 | H22: {=INDEX(成本核算表!J:J,MATCH(1,(成本核算表!D:D=E22)*(成本核算表!C:C=G22),0))} -> 12 | I22: 810 | J22: =H22*I22 -> 9720 | N22: =J22-M22+L22 -> 9720 | O22: =N22/3600 -> 2.7
A23: 46100 | B23: 11 | C23: =SUM(O23:O24)/B23 -> 1.2206061 | D23: 26020502-02 | E23: 105-331 | F23: 119.5 | G23: 冲弯 | H23: {=INDEX(成本核算表!J:J,MATCH(1,(成本核算表!D:D=E23)*(成本核算表!C:C=G23),0))} -> 12 | I23: 3228 | J23: =H23*I23 -> 38736 | N23: =J23-M23+L23 -> 38736 | O23: =N23/3600 -> 10.76
A24: 46100 | D24: 26020502-03 | E24: 105-331 | F24: 119.5 | G24: 冲弯 | H24: {=INDEX(成本核算表!J:J,MATCH(1,(成本核算表!D:D=E24)*(成本核算表!C:C=G24),0))} -> 12 | I24: 800 | J24: =H24*I24 -> 9600 | N24: =J24-M24+L24 -> 9600 | O24: =N24/3600 -> 2.6666667
A25: 46101 | B25: 11 | C25: =SUM(O25:O26)/B25 -> 1.2857576 | D25: 26020502-02 | E25: 105-331 | F25: 119.5 | G25: 冲弯 | H25: {=INDEX(成本核算表!J:J,MATCH(1,(成本核算表!D:D=E25)*(成本核算表!C:C=G25),0))} -> 12 | I25: 3643 | J25: =H25*I25 -> 43716 | N25: =J25-M25+L25 -> 43716 | O25: =N25/3600 -> 12.143333
A26: 46101 | D26: 26020502-03 | E26: 105-331 | F26: 119.5 | G26: 冲弯 | H26: {=INDEX(成本核算表!J:J,MATCH(1,(成本核算表!D:D=E26)*(成本核算表!C:C=G26),0))} -> 12 | I26: 600 | J26: =H26*I26 -> 7200 | N26: =J26-M26+L26 -> 7200 | O26: =N26/3600 -> 2
H27: {=INDEX(成本核算表!J:J,MATCH(1,(成本核算表!D:D=E27)*(成本核算表!C:C=G27),0))} -> 0 | J27: =H27*I27 -> 0 | N27: =J27-M27+L27 -> 0 | O27: =N27/3600 -> 0
H28: {=INDEX(成本核算表!J:J,MATCH(1,(成本核算表!D:D=E28)*(成本核算表!C:C=G28),0))} -> 0 | J28: =H28*I28 -> 0 | N28: =J28-M28+L28 -> 0 | O28: =N28/3600 -> 0
H29: {=INDEX(成本核算表!J:J,MATCH(1,(成本核算表!D:D=E29)*(成本核算表!C:C=G29),0))} -> 0 | J29: =H29*I29 -> 0 | N29: =J29-M29+L29 -> 0 | O29: =N29/3600 -> 0
H30: {=INDEX(成本核算表!J:J,MATCH(1,(成本核算表!D:D=E30)*(成本核算表!C:C=G30),0))} -> 0 | J30: =H30*I30 -> 0 | N30: =J30-M30+L30 -> 0 | O30: =N30/3600 -> 0
H31: {=INDEX(成本核算表!J:J,MATCH(1,(成本核算表!D:D=E31)*(成本核算表!C:C=G31),0))} -> 0 | J31: =H31*I31 -> 0 | N31: =J31-M31+L31 -> 0 | O31: =N31/3600 -> 0
H32: {=INDEX(成本核算表!J:J,MATCH(1,(成本核算表!D:D=E32)*(成本核算表!C:C=G32),0))} -> 0 | J32: =H32*I32 -> 0 | N32: =J32-M32+L32 -> 0 | O32: =N32/3600 -> 0
H33: {=INDEX(成本核算表!J:J,MATCH(1,(成本核算表!D:D=E33)*(成本核算表!C:C=G33),0))} -> 0 | J33: =H33*I33 -> 0 | N33: =J33-M33+L33 -> 0 | O33: =N33/3600 -> 0
H34: {=INDEX(成本核算表!J:J,MATCH(1,(成本核算表!D:D=E34)*(成本核算表!C:C=G34),0))} -> 0 | J34: =H34*I34 -> 0 | N34: =J34-M34+L34 -> 0 | O34: =N34/3600 -> 0
H35: {=INDEX(成本核算表!J:J,MATCH(1,(成本核算表!D:D=E35)*(成本核算表!C:C=G35),0))} -> 0 | J35: =H35*I35 -> 0 | N35: =J35-M35+L35 -> 0 | O35: =N35/3600 -> 0
H36: {=INDEX(成本核算表!J:J,MATCH(1,(成本核算表!D:D=E36)*(成本核算表!C:C=G36),0))} -> 0 | J36: =H36*I36 -> 0 | N36: =J36-M36+L36 -> 0 | O36: =N36/3600 -> 0
H37: {=INDEX(成本核算表!J:J,MATCH(1,(成本核算表!D:D=E37)*(成本核算表!C:C=G37),0))} -> 0 | J37: =H37*I37 -> 0 | N37: =J37-M37+L37 -> 0 | O37: =N37/3600 -> 0
H38: {=INDEX(成本核算表!J:J,MATCH(1,(成本核算表!D:D=E38)*(成本核算表!C:C=G38),0))} -> 0 | J38: =H38*I38 -> 0 | N38: =J38-M38+L38 -> 0 | O38: =N38/3600 -> 0
... H100: {=INDEX(成本核算表!J:J,MATCH(1,(成本核算表!D:D=E100)*(成本核算表!C:C=G100),0))} -> 0 | J100: =H100*I100 -> 0 | N100: =J100-M100+L100 -> 0 | O100: =N100/3600 -> 0
J101: =H101*I101 -> 0 | N101: =J101-M101+L101 -> 0 | O101: =N101/3600 -> 0

Sheet 向玲
A1: 日期 | B1: 出勤工时 | C1: 工时效率 | D1: 项目号 | E1: 产品型号 | F1: 长度（mm） | G1: 工序 | H1: 单件标准工时（S/支） | I1: 合格产量（支数） | J1: 合格工时（S） | K1: 个人不良产量（支数） | L1: 加分项 | M1: 减分项 | N1: 考核合计工时（秒） | O1: 合计（小时） | P1: 说明 | Q1: 备注
A2: 46082 | B2: 9.5 | C2: =SUM(O2:O4)/B2 -> 0.97836257 | D2: 26022708-06 | E2: 180-259 | F2: 1150 | G2: 打孔1 | H2: {=INDEX(成本核算表!J:J,MATCH(1,(成本核算表!D:D=E2)*(成本核算表!C:C=G2),0))} -> 15 | I2: 520 | J2: =H2*I2 -> 7800 | N2: =J2-M2+L2 -> 7800 | O2: =N2/3600 -> 2.1666667
A3: 46082 | D3: 26022708-06 | E3: 180-259 | F3: 1150 | G3: 打孔2 | H3: {=INDEX(成本核算表!J:J,MATCH(1,(成本核算表!D:D=E3)*(成本核算表!C:C=G3),0))} -> 25 | I3: 522 | J3: =H3*I3 -> 13050 | K3: =2*2 -> 4 | M3: =K3*H3 -> 100 | N3: =J3-M3+L3 -> 12950 | O3: =N3/3600 -> 3.5972222
A4: 46082 | D4: 26020502-02 | E4: 105-331 | F4: 119.5 | G4: 冲切 | H4: {=INDEX(成本核算表!J:J,MATCH(1,(成本核算表!D:D=E4)*(成本核算表!C:C=G4),0))} -> 10 | I4: 1271 | J4: =H4*I4 -> 12710 | N4: =J4-M4+L4 -> 12710 | O4: =N4/3600 -> 3.5305556
A5: 46083 | B5: 11 | C5: =SUM(O5:O7)/B5 -> 0.90901515 | D5: 26020502-02 | E5: 105-331 | F5: 119.5 | G5: 冲弯 | H5: {=INDEX(成本核算表!J:J,MATCH(1,(成本核算表!D:D=E5)*(成本核算表!C:C=G5),0))} -> 12 | I5: 596 | J5: =H5*I5 -> 7152 | N5: =J5-M5+L5 -> 7152 | O5: =N5/3600 -> 1.9866667
A6: 46083 | D6: 26020502-03 | E6: 105-331 | F6: 119.5 | G6: 冲弯 | H6: {=INDEX(成本核算表!J:J,MATCH(1,(成本核算表!D:D=E6)*(成本核算表!C:C=G6),0))} -> 12 | I6: 1160 | J6: =H6*I6 -> 13920 | N6: =J6-M6+L6 -> 13920 | O6: =N6/3600 -> 3.8666667
A7: 46083 | D7: 26013005-04 | E7: 262-1791 | F7: 1990 | G7: 冲孔2 | H7: {=INDEX(成本核算表!J:J,MATCH(1,(成本核算表!D:D=E7)*(成本核算表!C:C=G7),0))} -> 25 | I7: 597 | J7: =H7*I7 -> 14925 | N7: =J7-M7+L7 -> 14925 | O7: =N7/3600 -> 4.1458333
A8: 46084 | B8: 11 | C8: =SUM(O8:O9)/B8 -> 1.0153535 | D8: 26020502-02 | E8: 105-331 | F8: 119.5 | G8: 冲弯 | H8: {=INDEX(成本核算表!J:J,MATCH(1,(成本核算表!D:D=E8)*(成本核算表!C:C=G8),0))} -> 12 | I8: =1313+750 -> 2063 | J8: =H8*I8 -> 24756 | N8: =J8-M8+L8 -> 24756 | O8: =N8/3600 -> 6.8766667
A9: 46084 | D9: 26020502-02 | E9: 105-331 | F9: 119.5 | G9: 检验 | H9: {=INDEX(成本核算表!J:J,MATCH(1,(成本核算表!D:D=E9)*(成本核算表!C:C=G9),0))} -> 4 | I9: =1313+750 -> 2063 | J9: =H9*I9 -> 8252 | L9: 7200 | N9: =J9-M9+L9 -> 15452 | O9: =N9/3600 -> 4.2922222
A10: 46085 | B10: 11 | C10: =SUM(O10:O15)/B10 -> 1.082702 | D10: 26022711-07 | E10: 180-259 | F10: 950 | G10: 打孔1 | H10: {=INDEX(成本核算表!J:J,MATCH(1,(成本核算表!D:D=E10)*(成本核算表!C:C=G10),0))} -> 15 | I10: 610 | J10: =H10*I10 -> 9150 | N10: =J10-M10+L10 -> 9150 | O10: =N10/3600 -> 2.5416667
A11: 46085 | D11: 26022711-07 | E11: 180-259 | F11: 950 | G11: 打孔2 | H11: {=INDEX(成本核算表!J:J,MATCH(1,(成本核算表!D:D=E11)*(成本核算表!C:C=G11),0))} -> 25 | I11: 610 | J11: =H11*I11 -> 15250 | N11: =J11-M11+L11 -> 15250 | O11: =N11/3600 -> 4.2361111
A12: 46085 | D12: 26022710-07 | E12: 180-259 | F12: 950 | G12: 打孔1 | H12: {=INDEX(成本核算表!J:J,MATCH(1,(成本核算表!D:D=E12)*(成本核算表!C:C=G12),0))} -> 15 | I12: 90 | J12: =H12*I12 -> 1350 | N12: =J12-M12+L12 -> 1350 | O12: =N12/3600 -> 0.375
A13: 46085 | D13: 26022710-07 | E13: 180-259 | F13: 950 | G13: 打孔2 | H13: {=INDEX(成本核算表!J:J,MATCH(1,(成本核算表!D:D=E13)*(成本核算表!C:C=G13),0))} -> 25 | I13: 90 | J13: =H13*I13 -> 2250 | N13: =J13-M13+L13 -> 2250 | O13: =N13/3600 -> 0.625
A14: 46085 | D14: 26022709-03 | E14: 180-259 | F14: 950 | G14: 打孔1 | H14: {=INDEX(成本核算表!J:J,MATCH(1,(成本核算表!D:D=E14)*(成本核算表!C:C=G14),0))} -> 15 | I14: 360 | J14: =H14*I14 -> 5400 | N14: =J14-M14+L14 -> 5400 | O14: =N14/3600 -> 1.5
A15: 46085 | D15: 26022709-03 | E15: 180-259 | F15: 950 | G15: 打孔2 | H15: {=INDEX(成本核算表!J:J,MATCH(1,(成本核算表!D:D=E15)*(成本核算表!C:C=G15),0))} -> 25 | I15: 379 | J15: =H15*I15 -> 9475 | N15: =J15-M15+L15 -> 9475 | O15: =N15/3600 -> 2.6319444
A16: 46086 | B16: 11 | C16: =SUM(O16)/B16 -> 0.96060606 | D16: 26020502-03 | E16: 105-331 | F16: 119.5 | G16: 冲弯 | H16: {=INDEX(成本核算表!J:J,MATCH(1,(成本核算表!D:D=E16)*(成本核算表!C:C=G16),0))} -> 12 | I16: 3170 | J16: =H16*I16 -> 38040 | N16: =J16-M16+L16 -> 38040 | O16: =N16/3600 -> 10.566667
A17: 46087 | B17: 11 | C17: =SUM(O17)/B17 -> 0.93333333 | D17: 26020502-03 | E17: 105-331 | F17: 119.5 | G17: 冲弯 | H17: {=INDEX(成本核算表!J:J,MATCH(1,(成本核算表!D:D=E17)*(成本核算表!C:C=G17),0))} -> 12 | I17: 3080 | J17: =H17*I17 -> 36960 | N17: =J17-M17+L17 -> 36960 | O17: =N17/3600 -> 10.266667
A18: 46088 | B18: 11 | C18: =SUM(O18:O19)/B18 -> 1.0018182 | D18: 26020502-03 | E18: 105-331 | F18: 119.5 | G18: 冲弯 | H18: {=INDEX(成本核算表!J:J,MATCH(1,(成本核算表!D:D=E18)*(成本核算表!C:C=G18),0))} -> 12 | I18: 1156 | J18: =H18*I18 -> 13872 | L18: 18000 | N18: =J18-M18+L18 -> 31872 | O18: =N18/3600 -> 8.8533333
A19: 46088 | D19: 26020502-02 | E19: 105-331 | F19: 119.5 | G19: 冲弯 | H19: {=INDEX(成本核算表!J:J,MATCH(1,(成本核算表!D:D=E19)*(成本核算表!C:C=G19),0))} -> 12 | I19: 650 | J19: =H19*I19 -> 7800 | N19: =J19-M19+L19 -> 7800 | O19: =N19/3600 -> 2.1666667
A20: 46089 | B20: 4 | C20: =SUM(O20)/B20 -> 0.83333333 | D20: 26020502-03 | E20: 105-331 | F20: 119.5 | G20: 冲弯 | H20: {=INDEX(成本核算表!J:J,MATCH(1,(成本核算表!D:D=E20)*(成本核算表!C:C=G20),0))} -> 12 | I20: 700 | J20: =H20*I20 -> 8400 | L20: 3600 | N20: =J20-M20+L20 -> 12000 | O20: =N20/3600 -> 3.3333333
A21: 46090 | B21: 11 | C21: =SUM(O21:O24)/B21 -> 0.93376263 | D21: 26012706-05 | E21: 213-138 | F21: 1825 | G21: 冲孔 | H21: {=INDEX(成本核算表!J:J,MATCH(1,(成本核算表!D:D=E21)*(成本核算表!C:C=G21),0))} -> 25 | I21: 258 | J21: =H21*I21 -> 6450 | N21: =J21-M21+L21 -> 6450 | O21: =N21/3600 -> 1.7916667
A22: 46090 | D22: 26021003-03 | E22: 213-138 | F22: 1825 | G22: 冲孔 | H22: {=INDEX(成本核算表!J:J,MATCH(1,(成本核算表!D:D=E22)*(成本核算表!C:C=G22),0))} -> 25 | I22: 539 | J22: =H22*I22 -> 13475 | N22: =J22-M22+L22 -> 13475 | O22: =N22/3600 -> 3.7430556
A23: 46090 | D23: 26022605-07 | E23: 180-265 | F23: 950 | G23: 冲缺口 | H23: {=INDEX(成本核算表!J:J,MATCH(1,(成本核算表!D:D=E23)*(成本核算表!C:C=G23),0))} -> 12 | I23: 621 | J23: =H23*I23 -> 7452 | N23: =J23-M23+L23 -> 7452 | O23: =N23/3600 -> 2.07
A24: 46090 | D24: 26022605-01 | E24: 180-260 | F24: 1200 | G24: 冲缺口 | H24: {=INDEX(成本核算表!J:J,MATCH(1,(成本核算表!D:D=E24)*(成本核算表!C:C=G24),0))} -> 12 | I24: 800 | J24: =H24*I24 -> 9600 | N24: =J24-M24+L24 -> 9600 | O24: =N24/3600 -> 2.6666667
A25: 46091 | B25: 11 | C25: =SUM(O25:O28)/B25 -> 1.0258838 | D25: 26022605-01 | E25: 180-260 | F25: 1200 | G25: 冲缺口 | H25: {=INDEX(成本核算表!J:J,MATCH(1,(成本核算表!D:D=E25)*(成本核算表!C:C=G25),0))} -> 12 | I25: 785 | J25: =H25*I25 -> 9420 | L25: 7200 | N25: =J25-M25+L25 -> 16620 | O25: =N25/3600 -> 4.6166667 | Q25: 多岗
A26: 46091 | D26: 26010702-05 | E26: 286-470 | F26: 156 | G26: 冲孔 | H26: {=INDEX(成本核算表!J:J,MATCH(1,(成本核算表!D:D=E26)*(成本核算表!C:C=G26),0))} -> 15 | I26: 1133 | J26: =H26*I26 -> 16995 | N26: =J26-M26+L26 -> 16995 | O26: =N26/3600 -> 4.7208333
A27: 46091 | D27: 26010702-04 | E27: 286-469 | F27: 156 | G27: 冲孔 | H27: {=INDEX(成本核算表!J:J,MATCH(1,(成本核算表!D:D=E27)*(成本核算表!C:C=G27),0))} -> 15 | I27: 150 | J27: =H27*I27 -> 2250 | N27: =J27-M27+L27 -> 2250 | O27: =N27/3600 -> 0.625
A28: 46091 | D28: 26022712-01 | E28: 01-418 | F28: 4166 | G28: 冲孔2 | H28: {=INDEX(成本核算表!J:J,MATCH(1,(成本核算表!D:D=E28)*(成本核算表!C:C=G28),0))} -> 70 | I28: 68 | J28: =H28*I28 -> 4760 | N28: =J28-M28+L28 -> 4760 | O28: =N28/3600 -> 1.3222222
A29: 46092 | B29: 11 | C29: =SUM(O29:O32)/B29 -> 0.95151515 | D29: 26022504-04 | E29: 213-553 | F29: 1960 | G29: 冲六角孔 | H29: {=INDEX(成本核算表!J:J,MATCH(1,(成本核算表!D:D=E29)*(成本核算表!C:C=G29),0))} -> 15 | I29: =65+158 -> 223 | J29: =H29*I29 -> 3345 | N29: =J29-M29+L29 -> 3345 | O29: =N29/3600 -> 0.92916667
A30: 46092 | D30: 26022504-03 | E30: 213-553 | F30: 1960 | G30: 冲牙齿 | H30: {=INDEX(成本核算表!J:J,MATCH(1,(成本核算表!D:D=E30)*(成本核算表!C:C=G30),0))} -> 25 | I30: 245 | J30: =H30*I30 -> 6125 | N30: =J30-M30+L30 -> 6125 | O30: =N30/3600 -> 1.7013889
A31: 46092 | D31: 26022504-04 | E31: 213-553 | F31: 1960 | G31: 冲牙齿 | H31: {=INDEX(成本核算表!J:J,MATCH(1,(成本核算表!D:D=E31)*(成本核算表!C:C=G31),0))} -> 25 | I31: 154 | J31: =H31*I31 -> 3850 | N31: =J31-M31+L31 -> 3850 | O31: =N31/3600 -> 1.0694444
A32: 46092 | D32: 26020502-02 | E32: 105-331 | F32: 119.5 | G32: 冲弯 | H32: {=INDEX(成本核算表!J:J,MATCH(1,(成本核算表!D:D=E32)*(成本核算表!C:C=G32),0))} -> 12 | I32: 2030 | J32: =H32*I32 -> 24360 | N32: =J32-M32+L32 -> 24360 | O32: =N32/3600 -> 6.7666667
A33: 46093 | B33: 11 | C33: =SUM(O33:O37)/B33 -> 0.58560606 | D33: 26022504-04 | E33: 213-553 | F33: 1960 | G33: 冲葫芦孔 | H33: {=INDEX(成本核算表!J:J,MATCH(1,(成本核算表!D:D=E33)*(成本核算表!C:C=G33),0))} -> 15 | I33: 150 | J33: =H33*I33 -> 2250 | N33: =J33-M33+L33 -> 2250 | O33: =N33/3600 -> 0.625
A34: 46093 | D34: 26022504-03 | E34: 213-553 | F34: 1960 | G34: 冲葫芦孔 | H34: {=INDEX(成本核算表!J:J,MATCH(1,(成本核算表!D:D=E34)*(成本核算表!C:C=G34),0))} -> 15 | I34: 300 | J34: =H34*I34 -> 4500 | N34: =J34-M34+L34 -> 4500 | O34: =N34/3600 -> 1.25
A35: 46093 | D35: 26022504-03 | E35: 213-553 | F35: 1960 | G35: 冲六角孔 | H35: {=INDEX(成本核算表!J:J,MATCH(1,(成本核算表!D:D=E35)*(成本核算表!C:C=G35),0))} -> 15 | I35: =300+326 -> 626 | J35: =H35*I35 -> 9390 | N35: =J35-M35+L35 -> 9390 | O35: =N35/3600 -> 2.6083333
A36: 46093 | D36: 26022504-04 | E36: 213-553 | F36: 1960 | G36: 冲六角孔 | H36: {=INDEX(成本核算表!J:J,MATCH(1,(成本核算表!D:D=E36)*(成本核算表!C:C=G36),0))} -> 15 | I36: =169+104 -> 273 | J36: =H36*I36 -> 4095 | N36: =J36-M36+L36 -> 4095 | O36: =N36/3600 -> 1.1375
A37: 46093 | D37: 26022504-02 | E37: 213-553 | F37: 780 | G37: 冲葫芦孔 | H37: {=INDEX(成本核算表!J:J,MATCH(1,(成本核算表!D:D=E37)*(成本核算表!C:C=G37),0))} -> 15 | I37: 197 | J37: =H37*I37 -> 2955 | N37: =J37-M37+L37 -> 2955 | O37: =N37/3600 -> 0.82083333
A38: 46094 | B38: 11 | C38: =SUM(O38:O42)/B38 -> 0.68977273 | D38: 26022504-04 | E38: 213-553 | F38: 1960 | G38: 冲六角孔 | H38: {=INDEX(成本核算表!J:J,MATCH(1,(成本核算表!D:D=E38)*(成本核算表!C:C=G38),0))} -> 15 | I38: =175+288 -> 463 | J38: =H38*I38 -> 6945 | N38: =J38-M38+L38 -> 6945 | O38: =N38/3600 -> 1.9291667
A39: 46094 | D39: 26022504-04 | E39: 213-553 | F39: 1960 | G39: 冲葫芦孔 | H39: {=INDEX(成本核算表!J:J,MATCH(1,(成本核算表!D:D=E39)*(成本核算表!C:C=G39),0))} -> 15 | I39: =279+287 -> 566 | J39: =H39*I39 -> 8490 | N39: =J39-M39+L39 -> 8490 | O39: =N39/3600 -> 2.3583333
A40: 46094 | D40: 26022504-03 | E40: 213-553 | F40: 1960 | G40: 冲六角孔 | H40: {=INDEX(成本核算表!J:J,MATCH(1,(成本核算表!D:D=E40)*(成本核算表!C:C=G40),0))} -> 15 | I40: 297 | J40: =H40*I40 -> 4455 | N40: =J40-M40+L40 -> 4455 | O40: =N40/3600 -> 1.2375
...

Sheet 陆康
A1: 日期 | B1: 出勤工时 | C1: 工时效率 | D1: 项目号 | E1: 产品型号 | F1: 长度（mm） | G1: 工序 | H1: 单件标准工时（S/支） | I1: 合格产量（支数） | J1: 合格工时（S） | K1: 个人不良产量（支数） | L1: 加分项 | M1: 减分项 | N1: 考核合计工时（秒） | O1: 合计（小时） | P1: 说明 | Q1: 备注
A2: 46082 | B2: 9.5 | C2: =O2/B2 -> 1.3675439 | D2: 26020502-03 | E2: 105-331 | F2: 119.5 | G2: 倒角 | H2: {=INDEX(成本核算表!J:J,MATCH(1,(成本核算表!D:D=E2)*(成本核算表!C:C=G2),0))} -> 15 | I2: 3118 | J2: =H2*I2 -> 46770 | N2: =J2-M2+L2 -> 46770 | O2: =N2/3600 -> 12.991667
A3: 46083 | B3: 11 | C3: =SUM(O3:O4)/B3 -> 1.2454545 | D3: 26020502-03 | E3: 105-331 | F3: 119.5 | G3: 倒角 | H3: {=INDEX(成本核算表!J:J,MATCH(1,(成本核算表!D:D=E3)*(成本核算表!C:C=G3),0))} -> 15 | I3: 2360 | J3: =H3*I3 -> 35400 | N3: =J3-M3+L3 -> 35400 | O3: =N3/3600 -> 9.8333333
A4: 46083 | D4: 26020502-03 | E4: 105-331 | F4: 119.5 | G4: 沉孔 | H4: {=INDEX(成本核算表!J:J,MATCH(1,(成本核算表!D:D=E4)*(成本核算表!C:C=G4),0))} -> 12 | I4: 1160 | J4: =H4*I4 -> 13920 | N4: =J4-M4+L4 -> 13920 | O4: =N4/3600 -> 3.8666667
A5: 46084 | B5: 9 | C5: =O5/B5 -> 1.3888889 | D5: 26020502-03 | E5: 105-331 | F5: 119.5 | G5: 倒角 | H5: {=INDEX(成本核算表!J:J,MATCH(1,(成本核算表!D:D=E5)*(成本核算表!C:C=G5),0))} -> 15 | I5: 3000 | J5: =H5*I5 -> 45000 | N5: =J5-M5+L5 -> 45000 | O5: =N5/3600 -> 12.5
J6: =H6*I6 -> 0 | N6: =J6-M6+L6 -> 0 | O6: =N6/3600 -> 0
A7: 46086 | B7: 11 | C7: =O7/B7 -> 1.0154882 | E7: 113-54 | F7: 138.8 | G7: 抛光 | H7: {=INDEX(成本核算表!J:J,MATCH(1,(成本核算表!D:D=E7)*(成本核算表!C:C=G7),0))} -> 160 | I7: =754/3 -> 251.33333 | J7: =H7*I7 -> 40213.333 | M7: =K7*H7 -> 0 | N7: =J7-M7+L7 -> 40213.333 | O7: =N7/3600 -> 11.17037
A8: 46087 | B8: 11 | C8: =SUM(O8:O10)/B8 -> 0.94363636 | D8: 26020502-02 | E8: 105-331 | F8: 119.5 | G8: 倒角 | H8: {=INDEX(成本核算表!J:J,MATCH(1,(成本核算表!D:D=E8)*(成本核算表!C:C=G8),0))} -> 15 | I8: 424 | J8: =H8*I8 -> 6360 | N8: =J8-M8+L8 -> 6360 | O8: =N8/3600 -> 1.7666667
A9: 46087 | D9: 26020502-02 | E9: 105-331 | F9: 119.5 | G9: 沉孔 | H9: {=INDEX(成本核算表!J:J,MATCH(1,(成本核算表!D:D=E9)*(成本核算表!C:C=G9),0))} -> 12 | I9: 1124 | J9: =H9*I9 -> 13488 | N9: =J9-M9+L9 -> 13488 | O9: =N9/3600 -> 3.7466667
A10: 46087 | D10: 26020502-03 | E10: 105-331 | F10: 119.5 | G10: 沉孔 | H10: {=INDEX(成本核算表!J:J,MATCH(1,(成本核算表!D:D=E10)*(成本核算表!C:C=G10),0))} -> 12 | I10: 1460 | J10: =H10*I10 -> 17520 | N10: =J10-M10+L10 -> 17520 | O10: =N10/3600 -> 4.8666667
J11: =H11*I11 -> 0 | N11: =J11-M11+L11 -> 0 | O11: =N11/3600 -> 0
A12: 46089 | B12: 12 | C12: =SUM(O12:O13)/B12 -> 1.0416667 | D12: 26030705-01 | E12: 196-114 | F12: 2569.2 | G12: CNC | H12: {=INDEX(成本核算表!J:J,MATCH(1,(成本核算表!D:D=E12)*(成本核算表!C:C=G12),0))} -> 600 | I12: 15 | J12: =H12*I12 -> 9000 | N12: =J12-M12+L12 -> 9000 | O12: =N12/3600 -> 2.5
A13: 46089 | D13: 26030101-02 | E13: 196-114 | F13: 2296.8 | G13: CNC | H13: {=INDEX(成本核算表!J:J,MATCH(1,(成本核算表!D:D=E13)*(成本核算表!C:C=G13),0))} -> 600 | I13: 60 | J13: =H13*I13 -> 36000 | N13: =J13-M13+L13 -> 36000 | O13: =N13/3600 -> 10
A14: 46090 | B14: 12 | C14: =O14/B14 -> 1.0416667 | D14: 26030101-02 | E14: 196-114 | F14: 2296.8 | G14: CNC | H14: {=INDEX(成本核算表!J:J,MATCH(1,(成本核算表!D:D=E14)*(成本核算表!C:C=G14),0))} -> 600 | I14: 75 | J14: =H14*I14 -> 45000 | N14: =J14-M14+L14 -> 45000 | O14: =N14/3600 -> 12.5
A15: 46091 | B15: 12 | C15: =O15/B15 -> 1.0416667 | D15: 26030101-02 | E15: 196-114 | F15: 2296.8 | G15: CNC | H15: {=INDEX(成本核算表!J:J,MATCH(1,(成本核算表!D:D=E15)*(成本核算表!C:C=G15),0))} -> 600 | I15: 75 | J15: =H15*I15 -> 45000 | N15: =J15-M15+L15 -> 45000 | O15: =N15/3600 -> 12.5
A16: 46092 | B16: 12 | C16: =O16/B16 -> 1.0925926 | D16: 别墅梯 | E16: 286-337 | G16: 打孔 | H16: {=INDEX(成本核算表!J:J,MATCH(1,(成本核算表!D:D=E16)*(成本核算表!C:C=G16),0))} -> 100 | I16: =40+56+5+5+10+48+68+24+32+4+28+34+4+54+60 -> 472 | J16: =H16*I16 -> 47200 | N16: =J16-M16+L16 -> 47200 | O16: =N16/3600 -> 13.111111
A17: 46093 | B17: 12 | C17: =O17/B17 -> 0.65833333 | D17: 26020502-02 | E17: 105-331 | F17: 119.5 | G17: 沉孔 | H17: {=INDEX(成本核算表!J:J,MATCH(1,(成本核算表!D:D=E17)*(成本核算表!C:C=G17),0))} -> 12 | I17: 2370 | J17: =H17*I17 -> 28440 | N17: =J17-M17+L17 -> 28440 | O17: =N17/3600 -> 7.9
A18: 46094 | B18: 12 | C18: =SUM(O18:O21)/B18 -> 0.82252315 | D18: 26020502-02 | E18: 105-331 | F18: 119.5 | G18: 沉孔 | H18: {=INDEX(成本核算表!J:J,MATCH(1,(成本核算表!D:D=E18)*(成本核算表!C:C=G18),0))} -> 12 | I18: 534 | J18: =H18*I18 -> 6408 | N18: =J18-M18+L18 -> 6408 | O18: =N18/3600 -> 1.78
A19: 46094 | D19: 25090907-02 | E19: 113-80 | F19: 1942 | G19: 冲头孔 | H19: {=INDEX(成本核算表!J:J,MATCH(1,(成本核算表!D:D=E19)*(成本核算表!C:C=G19),0))} -> 25 | I19: 226 | J19: =H19*I19 -> 5650 | N19: =J19-M19+L19 -> 5650 | O19: =N19/3600 -> 1.5694444
A20: 46094 | D20: 25090907-02 | E20: 113-80 | F20: 1942 | G20: 沉孔 | H20: {=INDEX(成本核算表!J:J,MATCH(1,(成本核算表!D:D=E20)*(成本核算表!C:C=G20),0))} -> 35 | I20: 4 | J20: =H20*I20 -> 140 | K20: 19 | M20: =K20*H20 -> 665 | N20: =J20-M20+L20 -> -525 | O20: =N20/3600 -> -0.14583333
A21: 46094 | D21: 26020502-03 | E21: 105-331 | F21: 119.5 | G21: 倒角 | H21: {=INDEX(成本核算表!J:J,MATCH(1,(成本核算表!D:D=E21)*(成本核算表!C:C=G21),0))} -> 15 | I21: 1600 | J21: =H21*I21 -> 24000 | N21: =J21-M21+L21 -> 24000 | O21: =N21/3600 -> 6.6666667
A22: 46095 | B22: 12 | C22: =SUM(O22:O23)/B22 -> 1.0185185 | D22: 26020502-01 | E22: 105-330 | F22: 260 | G22: CNC1 | H22: {=INDEX(成本核算表!J:J,MATCH(1,(成本核算表!D:D=E22)*(成本核算表!C:C=G22),0))} -> 50 | I22: 400 | J22: =H22*I22 -> 20000 | N22: =J22-M22+L22 -> 20000 | O22: =N22/3600 -> 5.5555556
A23: 46095 | D23: 26020502-01 | E23: 105-330 | F23: 260 | G23: CNC2 | H23: {=INDEX(成本核算表!J:J,MATCH(1,(成本核算表!D:D=E23)*(成本核算表!C:C=G23),0))} -> 60 | I23: 400 | J23: =H23*I23 -> 24000 | N23: =J23-M23+L23 -> 24000 | O23: =N23/3600 -> 6.6666667
H24: {=INDEX(成本核算表!J:J,MATCH(1,(成本核算表!D:D=E24)*(成本核算表!C:C=G24),0))} -> 0 | I24: 400 | J24: =H24*I24 -> 0 | N24: =J24-M24+L24 -> 0 | O24: =N24/3600 -> 0
A25: 46097 | B25: 11 | C25: =O25/B25 -> 0.96484848 | D25: 26020502-03 | E25: 105-331 | F25: 119.5 | G25: 沉孔 | H25: {=INDEX(成本核算表!J:J,MATCH(1,(成本核算表!D:D=E25)*(成本核算表!C:C=G25),0))} -> 12 | I25: =1484+580+520 -> 2584 | J25: =H25*I25 -> 31008 | L25: 7200 | N25: =J25-M25+L25 -> 38208 | O25: =N25/3600 -> 10.613333 | Q25: 带新工
A26: 46098 | B26: 11 | C26: =O26/B26 -> 1.1709091 | D26: 26020502-03 | E26: 105-331 | F26: 119.5 | G26: 沉孔 | H26: {=INDEX(成本核算表!J:J,MATCH(1,(成本核算表!D:D=E26)*(成本核算表!C:C=G26),0))} -> 12 | I26: =1864+1400 -> 3264 | J26: =H26*I26 -> 39168 | L26: 7200 | N26: =J26-M26+L26 -> 46368 | O26: =N26/3600 -> 12.88 | Q26: 带新工
A27: 46099 | B27: 11 | C27: =O27/B27 -> 1.3636364 | D27: 26020502-03 | E27: 105-331 | F27: 119.5 | G27: 沉孔 | H27: {=INDEX(成本核算表!J:J,MATCH(1,(成本核算表!D:D=E27)*(成本核算表!C:C=G27),0))} -> 12 | I27: =2140+1760 -> 3900 | J27: =H27*I27 -> 46800 | L27: 7200 | N27: =J27-M27+L27 -> 54000 | O27: =N27/3600 -> 15 | Q27: 带新工
A28: 46100 | B28: 11 | C28: =O28/B28 -> 1.0345455 | D28: 26020502-03 | E28: 105-331 | F28: 119.5 | G28: 沉孔 | H28: {=INDEX(成本核算表!J:J,MATCH(1,(成本核算表!D:D=E28)*(成本核算表!C:C=G28),0))} -> 12 | I28: =2214 -> 2214 | J28: =H28*I28 -> 26568 | L28: =4*3600 -> 14400 | N28: =J28-M28+L28 -> 40968 | O28: =N28/3600 -> 11.38
A29: 46101 | B29: 11 | C29: =SUM(O29:O31)/B29 -> 0.99393939 | D29: 26020502-02 | E29: 105-331 | F29: 119.5 | G29: 沉孔 | H29: {=INDEX(成本核算表!J:J,MATCH(1,(成本核算表!D:D=E29)*(成本核算表!C:C=G29),0))} -> 12 | I29: 1000 | J29: =H29*I29 -> 12000 | L29: 14400 | N29: =J29-M29+L29 -> 26400 | O29: =N29/3600 -> 7.3333333 | Q29: 一楼整形
A30: 46101 | D30: 26020502-03 | E30: 105-331 | F30: 119.5 | G30: 沉孔 | H30: {=INDEX(成本核算表!J:J,MATCH(1,(成本核算表!D:D=E30)*(成本核算表!C:C=G30),0))} -> 12 | I30: 280 | J30: =H30*I30 -> 3360 | N30: =J30-M30+L30 -> 3360 | O30: =N30/3600 -> 0.93333333
A31: 46101 | D31: 26031205-01 | E31: 196-110 | F31: 1447 | G31: CNC | H31: {=INDEX(成本核算表!J:J,MATCH(1,(成本核算表!D:D=E31)*(成本核算表!C:C=G31),0))} -> 300 | I31: 32 | J31: =H31*I31 -> 9600 | N31: =J31-M31+L31 -> 9600 | O31: =N31/3600 -> 2.6666667
H32: {=INDEX(成本核算表!J:J,MATCH(1,(成本核算表!D:D=E32)*(成本核算表!C:C=G32),0))} -> 0 | J32: =H32*I32 -> 0 | N32: =J32-M32+L32 -> 0 | O32: =N32/3600 -> 0
H33: {=INDEX(成本核算表!J:J,MATCH(1,(成本核算表!D:D=E33)*(成本核算表!C:C=G33),0))} -> 0 | J33: =H33*I33 -> 0 | N33: =J33-M33+L33 -> 0 | O33: =N33/3600 -> 0
H34: {=INDEX(成本核算表!J:J,MATCH(1,(成本核算表!D:D=E34)*(成本核算表!C:C=G34),0))} -> 0 | J34: =H34*I34 -> 0 | N34: =J34-M34+L34 -> 0 | O34: =N34/3600 -> 0
H35: {=INDEX(成本核算表!J:J,MATCH(1,(成本核算表!D:D=E35)*(成本核算表!C:C=G35),0))} -> 0 | J35: =H35*I35 -> 0 | N35: =J35-M35+L35 -> 0 | O35: =N35/3600 -> 0
H36: {=INDEX(成本核算表!J:J,MATCH(1,(成本核算表!D:D=E36)*(成本核算表!C:C=G36),0))} -> 0 | J36: =H36*I36 -> 0 | N36: =J36-M36+L36 -> 0 | O36: =N36/3600 -> 0
H37: {=INDEX(成本核算表!J:J,MATCH(1,(成本核算表!D:D=E37)*(成本核算表!C:C=G37),0))} -> 0 | J37: =H37*I37 -> 0 | N37: =J37-M37+L37 -> 0 | O37: =N37/3600 -> 0
H38: {=INDEX(成本核算表!J:J,MATCH(1,(成本核算表!D:D=E38)*(成本核算表!C:C=G38),0))} -> 0 | J38: =H38*I38 -> 0 | N38: =J38-M38+L38 -> 0 | O38: =N38/3600 -> 0
H39: {=INDEX(成本核算表!J:J,MATCH(1,(成本核算表!D:D=E39)*(成本核算表!C:C=G39),0))} -> 0 | J39: =H39*I39 -> 0 | N39: =J39-M39+L39 -> 0 | O39: =N39/3600 -> 0
H40: {=INDEX(成本核算表!J:J,MATCH(1,(成本核算表!D:D=E40)*(成本核算表!C:C=G40),0))} -> 0 | J40: =H40*I40 -> 0 | N40: =J40-M40+L40 -> 0 | O40: =N40/3600 -> 0
...

Sheet 曹林
A1: 日期 | B1: 出勤工时 | C1: 工时效率 | D1: 项目号 | E1: 产品型号 | F1: 长度（mm） | G1: 工序 | H1: 单件标准工时（S/支） | I1: 合格产量（支数） | J1: 合格工时（S） | K1: 个人不良产量（支数） | L1: 加分项 | M1: 减分项 | N1: 考核合计工时（秒） | O1: 合计（小时） | P1: 说明 | Q1: 备注
A2: 46097 | B2: 11 | H2: {=INDEX(成本核算表!J:J,MATCH(1,(成本核算表!D:D=E2)*(成本核算表!C:C=G2),0))} -> 0 | J2: =H2*I2 -> 0 | L2: =11*3600 -> 39600 | N2: =J2-M2+L2 -> 39600 | O2: =N2/3600 -> 11
A3: 46098 | B3: 11 | H3: {=INDEX(成本核算表!J:J,MATCH(1,(成本核算表!D:D=E3)*(成本核算表!C:C=G3),0))} -> 0 | J3: =H3*I3 -> 0 | L3: =11*3600 -> 39600 | N3: =J3-M3+L3 -> 39600 | O3: =N3/3600 -> 11
A4: 46099 | B4: 11 | H4: {=INDEX(成本核算表!J:J,MATCH(1,(成本核算表!D:D=E4)*(成本核算表!C:C=G4),0))} -> 0 | J4: =H4*I4 -> 0 | L4: =11*3600 -> 39600 | N4: =J4-M4+L4 -> 39600 | O4: =N4/3600 -> 11
A5: 46100 | B5: 11 | H5: {=INDEX(成本核算表!J:J,MATCH(1,(成本核算表!D:D=E5)*(成本核算表!C:C=G5),0))} -> 0 | J5: =H5*I5 -> 0 | L5: =11*3600 -> 39600 | N5: =J5-M5+L5 -> 39600 | O5: =N5/3600 -> 11
A6: 46101 | B6: 11 | C6: =O6/B6 -> 0.79272727 | D6: 26020502-03 | E6: 105-331 | F6: 119.5 | G6: 沉孔 | H6: {=INDEX(成本核算表!J:J,MATCH(1,(成本核算表!D:D=E6)*(成本核算表!C:C=G6),0))} -> 12 | I6: 666 | J6: =H6*I6 -> 7992 | L6: =6.5*3600 -> 23400 | N6: =J6-M6+L6 -> 31392 | O6: =N6/3600 -> 8.72
H7: {=INDEX(成本核算表!J:J,MATCH(1,(成本核算表!D:D=E7)*(成本核算表!C:C=G7),0))} -> 0 | J7: =H7*I7 -> 0 | N7: =J7-M7+L7 -> 0 | O7: =N7/3600 -> 0
H8: {=INDEX(成本核算表!J:J,MATCH(1,(成本核算表!D:D=E8)*(成本核算表!C:C=G8),0))} -> 0 | J8: =H8*I8 -> 0 | N8: =J8-M8+L8 -> 0 | O8: =N8/3600 -> 0
H9: {=INDEX(成本核算表!J:J,MATCH(1,(成本核算表!D:D=E9)*(成本核算表!C:C=G9),0))} -> 0 | J9: =H9*I9 -> 0 | N9: =J9-M9+L9 -> 0 | O9: =N9/3600 -> 0
H10: {=INDEX(成本核算表!J:J,MATCH(1,(成本核算表!D:D=E10)*(成本核算表!C:C=G10),0))} -> 0 | J10: =H10*I10 -> 0 | N10: =J10-M10+L10 -> 0 | O10: =N10/3600 -> 0
H11: {=INDEX(成本核算表!J:J,MATCH(1,(成本核算表!D:D=E11)*(成本核算表!C:C=G11),0))} -> 0 | J11: =H11*I11 -> 0 | N11: =J11-M11+L11 -> 0 | O11: =N11/3600 -> 0
H12: {=INDEX(成本核算表!J:J,MATCH(1,(成本核算表!D:D=E12)*(成本核算表!C:C=G12),0))} -> 0 | J12: =H12*I12 -> 0 | N12: =J12-M12+L12 -> 0 | O12: =N12/3600 -> 0
H13: {=INDEX(成本核算表!J:J,MATCH(1,(成本核算表!D:D=E13)*(成本核算表!C:C=G13),0))} -> 0 | J13: =H13*I13 -> 0 | N13: =J13-M13+L13 -> 0 | O13: =N13/3600 -> 0
H14: {=INDEX(成本核算表!J:J,MATCH(1,(成本核算表!D:D=E14)*(成本核算表!C:C=G14),0))} -> 0 | J14: =H14*I14 -> 0 | N14: =J14-M14+L14 -> 0 | O14: =N14/3600 -> 0
H15: {=INDEX(成本核算表!J:J,MATCH(1,(成本核算表!D:D=E15)*(成本核算表!C:C=G15),0))} -> 0 | J15: =H15*I15 -> 0 | N15: =J15-M15+L15 -> 0 | O15: =N15/3600 -> 0
H16: {=INDEX(成本核算表!J:J,MATCH(1,(成本核算表!D:D=E16)*(成本核算表!C:C=G16),0))} -> 0 | J16: =H16*I16 -> 0 | N16: =J16-M16+L16 -> 0 | O16: =N16/3600 -> 0
H17: {=INDEX(成本核算表!J:J,MATCH(1,(成本核算表!D:D=E17)*(成本核算表!C:C=G17),0))} -> 0 | J17: =H17*I17 -> 0 | N17: =J17-M17+L17 -> 0 | O17: =N17/3600 -> 0
H18: {=INDEX(成本核算表!J:J,MATCH(1,(成本核算表!D:D=E18)*(成本核算表!C:C=G18),0))} -> 0 | J18: =H18*I18 -> 0 | N18: =J18-M18+L18 -> 0 | O18: =N18/3600 -> 0
... H77: {=INDEX(成本核算表!J:J,MATCH(1,(成本核算表!D:D=E77)*(成本核算表!C:C=G77),0))} -> 0 | J77: =H77*I77 -> 0 | N77: =J77-M77+L77 -> 0 | O77: =N77/3600 -> 0

Sheet 陈文香
A1: 日期 | B1: 出勤工时 | C1: 工时效率 | D1: 项目号 | E1: 产品型号 | F1: 长度（mm） | G1: 工序 | H1: 单件标准工时（S/支） | I1: 合格产量（支数） | J1: 合格工时（S） | K1: 个人不良产量（支数） | L1: 加分项 | M1: 减分项 | N1: 考核合计工时（秒） | O1: 合计（小时） | P1: 说明 | Q1: 备注
A2: 46082 | B2: 9.5 | C2: =O2/B2 -> 1.3532164 | D2: 25090907-02 | E2: 113-80 | F2: 1942 | G2: 打孔5个 | H2: {=INDEX(成本核算表!J:J,MATCH(1,(成本核算表!D:D=E2)*(成本核算表!C:C=G2),0))} -> 40 | I2: =1157 -> 1157 | J2: =H2*I2 -> 46280 | M2: =K2*H2 -> 0 | N2: =J2-M2+L2 -> 46280 | O2: =N2/3600 -> 12.855556
A3: 46083 | B3: 11 | C3: =SUM(O3:O4)/B3 -> 1.1464646 | D3: 25090907-01 | E3: 113-80 | F3: 1942 | G3: 打孔5个 | H3: {=INDEX(成本核算表!J:J,MATCH(1,(成本核算表!D:D=E3)*(成本核算表!C:C=G3),0))} -> 40 | I3: 507 | J3: =H3*I3 -> 20280 | M3: =K3*H3 -> 0 | N3: =J3-M3+L3 -> 20280 | O3: =N3/3600 -> 5.6333333
A4: 46083 | D4: 25090907-02 | E4: 113-80 | F4: 1942 | G4: 打孔5个 | H4: {=INDEX(成本核算表!J:J,MATCH(1,(成本核算表!D:D=E4)*(成本核算表!C:C=G4),0))} -> 40 | I4: 628 | J4: =H4*I4 -> 25120 | M4: =K4*H4 -> 0 | N4: =J4-M4+L4 -> 25120 | O4: =N4/3600 -> 6.9777778
A5: 46084 | B5: 9 | C5: =O5/B5 -> 1.1358025 | D5: 25062804-02 | E5: 113-54 | F5: 138.8 | G5: CNC | H5: {=INDEX(成本核算表!J:J,MATCH(1,(成本核算表!D:D=E5)*(成本核算表!C:C=G5),0))} -> 160 | I5: 230 | J5: =H5*I5 -> 36800 | M5: =K5*H5 -> 0 | N5: =J5-M5+L5 -> 36800 | O5: =N5/3600 -> 10.222222
J6: =H6*I6 -> 0 | M6: =K6*H6 -> 0 | N6: =J6-M6+L6 -> 0 | O6: =N6/3600 -> 0
A7: 46086 | B7: 11 | C7: =O7/B7 -> 1.0154882 | E7: 113-54 | F7: 138.8 | G7: CNC | H7: {=INDEX(成本核算表!J:J,MATCH(1,(成本核算表!D:D=E7)*(成本核算表!C:C=G7),0))} -> 160 | I7: =754/3 -> 251.33333 | J7: =H7*I7 -> 40213.333 | M7: =K7*H7 -> 0 | N7: =J7-M7+L7 -> 40213.333 | O7: =N7/3600 -> 11.17037
A8: 46087 | B8: 11 | C8: =SUM(O8:O10)/B8 -> 1.0362626 | D8: 26011505-01 | E8: 113-78 | F8: 138.8 | G8: CNC | H8: {=INDEX(成本核算表!J:J,MATCH(1,(成本核算表!D:D=E8)*(成本核算表!C:C=G8),0))} -> 300 | I8: 17 | J8: =H8*I8 -> 5100 | M8: =K8*H8 -> 0 | N8: =J8-M8+L8 -> 5100 | O8: =N8/3600 -> 1.4166667
A9: 46087 | D9: 26011505-02 | E9: 113-79 | F9: 138.8 | G9: CNC | H9: {=INDEX(成本核算表!J:J,MATCH(1,(成本核算表!D:D=E9)*(成本核算表!C:C=G9),0))} -> 276 | I9: 62 | J9: =H9*I9 -> 17112 | K9: 6 | M9: =K9*H9 -> 1656 | N9: =J9-M9+L9 -> 15456 | O9: =N9/3600 -> 4.2933333
A10: 46087 | E10: 113-54 | F10: 138.8 | G10: CNC | H10: {=INDEX(成本核算表!J:J,MATCH(1,(成本核算表!D:D=E10)*(成本核算表!C:C=G10),0))} -> 160 | I10: =384/3 -> 128 | J10: =H10*I10 -> 20480 | M10: =K10*H10 -> 0 | N10: =J10-M10+L10 -> 20480 | O10: =N10/3600 -> 5.6888889
J11: =H11*I11 -> 0 | M11: =K11*H11 -> 0 | N11: =J11-M11+L11 -> 0 | O11: =N11/3600 -> 0
A12: 46089 | B12: 12 | C12: =O12/B12 -> 0.96296296 | E12: 113-54 | F12: 138.8 | G12: CNC | H12: {=INDEX(成本核算表!J:J,MATCH(1,(成本核算表!D:D=E12)*(成本核算表!C:C=G12),0))} -> 160 | I12: 260 | J12: =H12*I12 -> 41600 | M12: =K12*H12 -> 0 | N12: =J12-M12+L12 -> 41600 | O12: =N12/3600 -> 11.555556
A13: 46090 | B13: 12 | C13: =O13/B13 -> 0.96296296 | E13: 113-54 | F13: 138.8 | G13: CNC | H13: {=INDEX(成本核算表!J:J,MATCH(1,(成本核算表!D:D=E13)*(成本核算表!C:C=G13),0))} -> 160 | I13: 260 | J13: =H13*I13 -> 41600 | M13: =K13*H13 -> 0 | N13: =J13-M13+L13 -> 41600 | O13: =N13/3600 -> 11.555556
A14: 46091 | B14: 12 | C14: =SUM(O14:O15)/B14 -> 0.98101852 | D14: 25090907-01 | E14: 113-80 | F14: 1942 | G14: CNC | H14: {=INDEX(成本核算表!J:J,MATCH(1,(成本核算表!D:D=E14)*(成本核算表!C:C=G14),0))} -> 65 | I14: 548 | J14: =H14*I14 -> 35620 | K14: 40 | M14: =K14*H14 -> 2600 | N14: =J14-M14+L14 -> 33020 | O14: =N14/3600 -> 9.1722222
A15: 46091 | D15: 25090907-02 | E15: 113-80 | F15: 1942 | G15: CNC | H15: {=INDEX(成本核算表!J:J,MATCH(1,(成本核算表!D:D=E15)*(成本核算表!C:C=G15),0))} -> 65 | I15: 160 | J15: =H15*I15 -> 10400 | K15: 16 | M15: =K15*H15 -> 1040 | N15: =J15-M15+L15 -> 9360 | O15: =N15/3600 -> 2.6
A16: 46092 | B16: 12 | C16: =SUM(O16:O17)/B16 -> 1.0728009 | D16: 25090907-01 | E16: 113-80 | F16: 1942 | G16: CNC | H16: {=INDEX(成本核算表!J:J,MATCH(1,(成本核算表!D:D=E16)*(成本核算表!C:C=G16),0))} -> 65 | I16: 693 | J16: =H16*I16 -> 45045 | M16: =K16*H16 -> 0 | N16: =J16-M16+L16 -> 45045 | O16: =N16/3600 -> 12.5125
A17: 46092 | D17: 25090907-02 | E17: 113-80 | F17: 1942 | G17: CNC | H17: {=INDEX(成本核算表!J:J,MATCH(1,(成本核算表!D:D=E17)*(成本核算表!C:C=G17),0))} -> 65 | I17: 20 | J17: =H17*I17 -> 1300 | M17: =K17*H17 -> 0 | N17: =J17-M17+L17 -> 1300 | O17: =N17/3600 -> 0.36111111
A18: 46093 | B18: 12 | C18: =SUM(O18)/B18 -> 1.0167824 | D18: 25090907-01 | E18: 113-80 | F18: 1942 | G18: 沉孔 | H18: {=INDEX(成本核算表!J:J,MATCH(1,(成本核算表!D:D=E18)*(成本核算表!C:C=G18),0))} -> 35 | I18: 1265 | J18: =H18*I18 -> 44275 | K18: 10 | M18: =K18*H18 -> 350 | N18: =J18-M18+L18 -> 43925 | O18: =N18/3600 -> 12.201389
A19: 46094 | B19: 12 | C19: =SUM(O19:O22)/B19 -> 1.0800926 | D19: 25090907-01 | E19: 113-80 | F19: 1942 | G19: CNC | H19: {=INDEX(成本核算表!J:J,MATCH(1,(成本核算表!D:D=E19)*(成本核算表!C:C=G19),0))} -> 65 | I19: 346 | J19: =H19*I19 -> 22490 | K19: 28 | M19: =K19*H19 -> 1820 | N19: =J19-M19+L19 -> 20670 | O19: =N19/3600 -> 5.7416667
A20: 46094 | D20: 25090907-02 | E20: 113-80 | F20: 1942 | G20: CNC | H20: {=INDEX(成本核算表!J:J,MATCH(1,(成本核算表!D:D=E20)*(成本核算表!C:C=G20),0))} -> 65 | I20: 226 | J20: =H20*I20 -> 14690 | K20: 8 | M20: =K20*H20 -> 520 | N20: =J20-M20+L20 -> 14170 | O20: =N20/3600 -> 3.9361111
A21: 46094 | D21: 26022504-04 | E21: 213-553 | F21: 1960 | G21: CNC | H21: {=INDEX(成本核算表!J:J,MATCH(1,(成本核算表!D:D=E21)*(成本核算表!C:C=G21),0))} -> 60 | I21: 16 | J21: =H21*I21 -> 960 | M21: =K21*H21 -> 0 | N21: =J21-M21+L21 -> 960 | O21: =N21/3600 -> 0.26666667
A22: 46094 | D22: 26022504-03 | E22: 213-553 | F22: 1960 | G22: CNC | H22: {=INDEX(成本核算表!J:J,MATCH(1,(成本核算表!D:D=E22)*(成本核算表!C:C=G22),0))} -> 60 | I22: 181 | J22: =H22*I22 -> 10860 | M22: =K22*H22 -> 0 | N22: =J22-M22+L22 -> 10860 | O22: =N22/3600 -> 3.0166667
A23: 46095 | B23: 12 | C23: =SUM(O23:O24)/B23 -> 1.0196759 | D23: 26030302-02 | E23: 180-261 | F23: 950 | G23: 冲安装孔 | H23: {=INDEX(成本核算表!J:J,MATCH(1,(成本核算表!D:D=E23)*(成本核算表!C:C=G23),0))} -> 25 | I23: 1200 | J23: =H23*I23 -> 30000 | M23: =K23*H23 -> 0 | N23: =J23-M23+L23 -> 30000 | O23: =N23/3600 -> 8.3333333
A24: 46095 | D24: 26030306-02 | E24: 180-261 | F24: 950 | G24: 冲安装孔 | H24: {=INDEX(成本核算表!J:J,MATCH(1,(成本核算表!D:D=E24)*(成本核算表!C:C=G24),0))} -> 25 | I24: 562 | J24: =H24*I24 -> 14050 | M24: =K24*H24 -> 0 | N24: =J24-M24+L24 -> 14050 | O24: =N24/3600 -> 3.9027778
H25: {=INDEX(成本核算表!J:J,MATCH(1,(成本核算表!D:D=E25)*(成本核算表!C:C=G25),0))} -> 0 | J25: =H25*I25 -> 0 | M25: =K25*H25 -> 0 | N25: =J25-M25+L25 -> 0 | O25: =N25/3600 -> 0
A26: 46097 | B26: 11 | C26: =SUM(O26:O27)/B26 -> 0.9260101 | D26: 26031503-01 | E26: 105-244 | F26: 2200 | G26: 冲腰孔 | H26: {=INDEX(成本核算表!J:J,MATCH(1,(成本核算表!D:D=E26)*(成本核算表!C:C=G26),0))} -> 13 | I26: 340 | J26: =H26*I26 -> 4420 | M26: =K26*H26 -> 0 | N26: =J26-M26+L26 -> 4420 | O26: =N26/3600 -> 1.2277778
A27: 46097 | D27: 26031503-02 | E27: 105-244 | F27: 2200 | G27: 冲缺口 | H27: {=INDEX(成本核算表!J:J,MATCH(1,(成本核算表!D:D=E27)*(成本核算表!C:C=G27),0))} -> 15 | I27: 2150 | J27: =H27*I27 -> 32250 | M27: =K27*H27 -> 0 | N27: =J27-M27+L27 -> 32250 | O27: =N27/3600 -> 8.9583333
A28: 46098 | B28: 11 | C28: =SUM(O28)/B28 -> 1.010101 | D28: 25062804-02 | E28: 113-54 | F28: 138.8 | G28: CNC | H28: {=INDEX(成本核算表!J:J,MATCH(1,(成本核算表!D:D=E28)*(成本核算表!C:C=G28),0))} -> 160 | I28: 260 | J28: =H28*I28 -> 41600 | K28: 10 | M28: =K28*H28 -> 1600 | N28: =J28-M28+L28 -> 40000 | O28: =N28/3600 -> 11.111111
A29: 46099 | B29: 11 | C29: =SUM(O29)/B29 -> 1.0020202 | D29: 25062804-02 | E29: 113-54 | F29: 138.8 | G29: CNC | H29: {=INDEX(成本核算表!J:J,MATCH(1,(成本核算表!D:D=E29)*(成本核算表!C:C=G29),0))} -> 160 | I29: 260 | J29: =H29*I29 -> 41600 | K29: 12 | M29: =K29*H29 -> 1920 | N29: =J29-M29+L29 -> 39680 | O29: =N29/3600 -> 11.022222
A30: 46100 | B30: 11 | C30: =SUM(O30:O31)/B30 -> 1.1181818 | E30: 180-259 | F30: 1500 | G30: CNC | H30: {=INDEX(成本核算表!J:J,MATCH(1,(成本核算表!D:D=E30)*(成本核算表!C:C=G30),0))} -> 110 | I30: 68 | J30: =H30*I30 -> 7480 | M30: =K30*H30 -> 0 | N30: =J30-M30+L30 -> 7480 | O30: =N30/3600 -> 2.0777778
A31: 46100 | D31: 25062804-02 | E31: 113-54 | F31: 138.8 | G31: CNC | H31: {=INDEX(成本核算表!J:J,MATCH(1,(成本核算表!D:D=E31)*(成本核算表!C:C=G31),0))} -> 160 | I31: 240 | J31: =H31*I31 -> 38400 | K31: 10 | M31: =K31*H31 -> 1600 | N31: =J31-M31+L31 -> 36800 | O31: =N31/3600 -> 10.222222
A32: 46101 | B32: 11 | C32: =SUM(O32:O35)/B32 -> 0.84469697 | D32: 26031301-03 | E32: 213-553 | F32: 1960 | G32: 冲葫芦孔 | H32: {=INDEX(成本核算表!J:J,MATCH(1,(成本核算表!D:D=E32)*(成本核算表!C:C=G32),0))} -> 15 | I32: 682 | J32: =H32*I32 -> 10230 | M32: =K32*H32 -> 0 | N32: =J32-M32+L32 -> 10230 | O32: =N32/3600 -> 2.8416667
A33: 46101 | D33: 26031301-03 | E33: 213-553 | F33: 1960 | G33: 冲六角孔 | H33: {=INDEX(成本核算表!J:J,MATCH(1,(成本核算表!D:D=E33)*(成本核算表!C:C=G33),0))} -> 15 | I33: 682 | J33: =H33*I33 -> 10230 | M33: =K33*H33 -> 0 | N33: =J33-M33+L33 -> 10230 | O33: =N33/3600 -> 2.8416667
A34: 46101 | D34: 26031301-04 | E34: 213-553 | F34: 1960 | G34: 冲葫芦孔 | H34: {=INDEX(成本核算表!J:J,MATCH(1,(成本核算表!D:D=E34)*(成本核算表!C:C=G34),0))} -> 15 | I34: 383 | J34: =H34*I34 -> 5745 | M34: =K34*H34 -> 0 | N34: =J34-M34+L34 -> 5745 | O34: =N34/3600 -> 1.5958333
A35: 46101 | D35: 26031301-04 | E35: 213-553 | F35: 1960 | G35: 冲六角孔 | H35: {=INDEX(成本核算表!J:J,MATCH(1,(成本核算表!D:D=E35)*(成本核算表!C:C=G35),0))} -> 15 | I35: 483 | J35: =H35*I35 -> 7245 | M35: =K35*H35 -> 0 | N35: =J35-M35+L35 -> 7245 | O35: =N35/3600 -> 2.0125
H36: {=INDEX(成本核算表!J:J,MATCH(1,(成本核算表!D:D=E36)*(成本核算表!C:C=G36),0))} -> 0 | J36: =H36*I36 -> 0 | M36: =K36*H36 -> 0 | N36: =J36-M36+L36 -> 0 | O36: =N36/3600 -> 0
H37: {=INDEX(成本核算表!J:J,MATCH(1,(成本核算表!D:D=E37)*(成本核算表!C:C=G37),0))} -> 0 | J37: =H37*I37 -> 0 | M37: =K37*H37 -> 0 | N37: =J37-M37+L37 -> 0 | O37: =N37/3600 -> 0
H38: {=INDEX(成本核算表!J:J,MATCH(1,(成本核算表!D:D=E38)*(成本核算表!C:C=G38),0))} -> 0 | J38: =H38*I38 -> 0 | M38: =K38*H38 -> 0 | N38: =J38-M38+L38 -> 0 | O38: =N38/3600 -> 0
H39: {=INDEX(成本核算表!J:J,MATCH(1,(成本核算表!D:D=E39)*(成本核算表!C:C=G39),0))} -> 0 | J39: =H39*I39 -> 0 | M39: =K39*H39 -> 0 | N39: =J39-M39+L39 -> 0 | O39: =N39/3600 -> 0
H40: {=INDEX(成本核算表!J:J,MATCH(1,(成本核算表!D:D=E40)*(成本核算表!C:C=G40),0))} -> 0 | J40: =H40*I40 -> 0 | M40: =K40*H40 -> 0 | N40: =J40-M40+L40 -> 0 | O40: =N40/3600 -> 0
...

Sheet 冯永惠
A1: 日期 | B1: 出勤工时 | C1: 工时效率 | D1: 项目号 | E1: 产品型号 | F1: 长度（mm） | G1: 工序 | H1: 单件标准工时（S/支） | I1: 合格产量（支数） | J1: 合格工时（S） | K1: 个人不良产量（支数） | L1: 加分项 | M1: 减分项 | N1: 考核合计工时（秒） | O1: 合计（小时） | P1: 说明 | Q1: 备注
A2: 46082 | B2: 12 | C2: =SUM(O2:O3)/B2 -> 1.1475 | D2: 26020502-03 | E2: 105-331 | F2: 119.5 | G2: 倒角 | H2: {=INDEX(成本核算表!J:J,MATCH(1,(成本核算表!D:D=E2)*(成本核算表!C:C=G2),0))} -> 15 | I2: 1216 | J2: =H2*I2 -> 18240 | N2: =J2-M2+L2 -> 18240 | O2: =N2/3600 -> 5.0666667
A3: 46082 | D3: 26020502-03 | E3: 105-331 | F3: 119.5 | G3: 沉孔 | H3: {=INDEX(成本核算表!J:J,MATCH(1,(成本核算表!D:D=E3)*(成本核算表!C:C=G3),0))} -> 12 | I3: 2611 | J3: =H3*I3 -> 31332 | N3: =J3-M3+L3 -> 31332 | O3: =N3/3600 -> 8.7033333
A4: 46083 | B4: 12 | C4: =SUM(O4:O5)/B4 -> 1.0185185 | D4: 26020502-01 | E4: 105-330 | F4: 260 | G4: CNC1 | H4: {=INDEX(成本核算表!J:J,MATCH(1,(成本核算表!D:D=E4)*(成本核算表!C:C=G4),0))} -> 50 | I4: 400 | J4: =H4*I4 -> 20000 | N4: =J4-M4+L4 -> 20000 | O4: =N4/3600 -> 5.5555556
A5: 46083 | D5: 26020502-01 | E5: 105-330 | F5: 260 | G5: CNC2 | H5: {=INDEX(成本核算表!J:J,MATCH(1,(成本核算表!D:D=E5)*(成本核算表!C:C=G5),0))} -> 60 | I5: 400 | J5: =H5*I5 -> 24000 | N5: =J5-M5+L5 -> 24000 | O5: =N5/3600 -> 6.6666667
A6: 46084 | B6: 12 | C6: =SUM(O6:O9)/B6 -> 0.57523148 | E6: 286-337 | G6: 打孔 | H6: {=INDEX(成本核算表!J:J,MATCH(1,(成本核算表!D:D=E6)*(成本核算表!C:C=G6),0))} -> 100 | I6: =55/2 -> 27.5 | J6: =H6*I6 -> 2750 | N6: =J6-M6+L6 -> 2750 | O6: =N6/3600 -> 0.76388889
A7: 46084 | D7: 26022708-05 | E7: 180-259 | F7: 950 | G7: 端铣 | H7: {=INDEX(成本核算表!J:J,MATCH(1,(成本核算表!D:D=E7)*(成本核算表!C:C=G7),0))} -> 20 | I7: =1030/2 -> 515 | J7: =H7*I7 -> 10300 | N7: =J7-M7+L7 -> 10300 | O7: =N7/3600 -> 2.8611111
A8: 46084 | D8: 26022708-08 | E8: 180-259 | F8: 1150 | G8: 端铣 | H8: {=INDEX(成本核算表!J:J,MATCH(1,(成本核算表!D:D=E8)*(成本核算表!C:C=G8),0))} -> 20 | I8: 15 | J8: =H8*I8 -> 300 | N8: =J8-M8+L8 -> 300 | O8: =N8/3600 -> 0.083333333
A9: 46084 | D9: 26022708-06 | E9: 180-259 | F9: 1150 | G9: 端铣 | H9: {=INDEX(成本核算表!J:J,MATCH(1,(成本核算表!D:D=E9)*(成本核算表!C:C=G9),0))} -> 20 | I9: =1150/2 -> 575 | J9: =H9*I9 -> 11500 | N9: =J9-M9+L9 -> 11500 | O9: =N9/3600 -> 3.1944444
A10: 46085 | B10: 12 | C10: =SUM(O10:O11)/B10 -> 1.0185185 | D10: 26020502-01 | E10: 105-330 | F10: 260 | G10: CNC1 | H10: {=INDEX(成本核算表!J:J,MATCH(1,(成本核算表!D:D=E10)*(成本核算表!C:C=G10),0))} -> 50 | I10: 400 | J10: =H10*I10 -> 20000 | N10: =J10-M10+L10 -> 20000 | O10: =N10/3600 -> 5.5555556
A11: 46085 | D11: 26020502-01 | E11: 105-330 | F11: 260 | G11: CNC2 | H11: {=INDEX(成本核算表!J:J,MATCH(1,(成本核算表!D:D=E11)*(成本核算表!C:C=G11),0))} -> 60 | I11: 400 | J11: =H11*I11 -> 24000 | N11: =J11-M11+L11 -> 24000 | O11: =N11/3600 -> 6.6666667
A12: 46086 | B12: 12 | C12: =SUM(O12)/B12 -> 0.75 | D12: 26020502-03 | E12: 105-331 | F12: 119.5 | G12: 沉孔 | H12: {=INDEX(成本核算表!J:J,MATCH(1,(成本核算表!D:D=E12)*(成本核算表!C:C=G12),0))} -> 12 | I12: 2400 | J12: =H12*I12 -> 28800 | L12: 3600 | N12: =J12-M12+L12 -> 32400 | O12: =N12/3600 -> 9
A13: 46087 | B13: 12 | C13: =SUM(O13)/B13 -> 0.50555556 | D13: 26020502-03 | E13: 105-331 | F13: 119.5 | G13: 沉孔 | H13: {=INDEX(成本核算表!J:J,MATCH(1,(成本核算表!D:D=E13)*(成本核算表!C:C=G13),0))} -> 12 | I13: 1820 | J13: =H13*I13 -> 21840 | N13: =J13-M13+L13 -> 21840 | O13: =N13/3600 -> 6.0666667
A14: 46088 | B14: 12 | C14: =C10 -> 1.0185185 | D14: 26020701-01 | E14: 180-217 | F14: 1633.7 | G14: CNC | H14: {=INDEX(成本核算表!J:J,MATCH(1,(成本核算表!D:D=E14)*(成本核算表!C:C=G14),0))} -> 400 | I14: 86 | J14: =H14*I14 -> 34400 | N14: =J14-M14+L14 -> 34400 | O14: =N14/3600 -> 9.5555556
A15: 46088 | D15: 26022505-01 | E15: 258-462 | F15: 140 | G15: CNC2 | H15: {=INDEX(成本核算表!J:J,MATCH(1,(成本核算表!D:D=E15)*(成本核算表!C:C=G15),0))} -> 700 | I15: 50 | J15: =H15*I15 -> 35000 | N15: =J15-M15+L15 -> 35000 | O15: =N15/3600 -> 9.7222222
H16: {=INDEX(成本核算表!J:J,MATCH(1,(成本核算表!D:D=E16)*(成本核算表!C:C=G16),0))} -> 0 | J16: =H16*I16 -> 0 | N16: =J16-M16+L16 -> 0 | O16: =N16/3600 -> 0
A17: 46090 | B17: 11 | C17: =SUM(O17)/B17 -> 1.1363636 | D17: 26030101-02 | E17: 196-114 | F17: 2296.8 | G17: CNC | H17: {=INDEX(成本核算表!J:J,MATCH(1,(成本核算表!D:D=E17)*(成本核算表!C:C=G17),0))} -> 600 | I17: 75 | J17: =H17*I17 -> 45000 | N17: =J17-M17+L17 -> 45000 | O17: =N17/3600 -> 12.5
A18: 46091 | B18: 11 | C18: =SUM(O18)/B18 -> 1.1363636 | D18: 26030101-02 | E18: 196-114 | F18: 2296.8 | G18: CNC | H18: {=INDEX(成本核算表!J:J,MATCH(1,(成本核算表!D:D=E18)*(成本核算表!C:C=G18),0))} -> 600 | I18: 75 | J18: =H18*I18 -> 45000 | N18: =J18-M18+L18 -> 45000 | O18: =N18/3600 -> 12.5
A19: 46092 | B19: 12 | C19: =SUM(O19)/B19 -> 0.49444444 | D19: 26020502-02 | E19: 105-331 | F19: 119.5 | G19: 沉孔 | H19: {=INDEX(成本核算表!J:J,MATCH(1,(成本核算表!D:D=E19)*(成本核算表!C:C=G19),0))} -> 12 | I19: 1780 | J19: =H19*I19 -> 21360 | N19: =J19-M19+L19 -> 21360 | O19: =N19/3600 -> 5.9333333
H20: {=INDEX(成本核算表!J:J,MATCH(1,(成本核算表!D:D=E20)*(成本核算表!C:C=G20),0))} -> 0 | J20: =H20*I20 -> 0 | N20: =J20-M20+L20 -> 0 | O20: =N20/3600 -> 0
H21: {=INDEX(成本核算表!J:J,MATCH(1,(成本核算表!D:D=E21)*(成本核算表!C:C=G21),0))} -> 0 | J21: =H21*I21 -> 0 | N21: =J21-M21+L21 -> 0 | O21: =N21/3600 -> 0
H22: {=INDEX(成本核算表!J:J,MATCH(1,(成本核算表!D:D=E22)*(成本核算表!C:C=G22),0))} -> 0 | J22: =H22*I22 -> 0 | N22: =J22-M22+L22 -> 0 | O22: =N22/3600 -> 0
A23: 46096 | B23: 12 | C23: =SUM(O23)/B23 -> 1.0416667 | D23: 26030101-02 | E23: 196-114 | F23: 2296.8 | G23: CNC | H23: {=INDEX(成本核算表!J:J,MATCH(1,(成本核算表!D:D=E23)*(成本核算表!C:C=G23),0))} -> 600 | I23: 75 | J23: =H23*I23 -> 45000 | N23: =J23-M23+L23 -> 45000 | O23: =N23/3600 -> 12.5
A24: 46097 | B24: 12 | C24: =SUM(O24)/B24 -> 1.0416667 | D24: 26030101-02 | E24: 196-114 | F24: 2296.8 | G24: CNC | H24: {=INDEX(成本核算表!J:J,MATCH(1,(成本核算表!D:D=E24)*(成本核算表!C:C=G24),0))} -> 600 | I24: 75 | J24: =H24*I24 -> 45000 | N24: =J24-M24+L24 -> 45000 | O24: =N24/3600 -> 12.5
A25: 46098 | B25: 12 | C25: =SUM(O25:O26)/B25 -> 0.90277778 | D25: 26022504-03 | E25: 213-553 | F25: 1960 | G25: 切割45° | H25: {=INDEX(成本核算表!J:J,MATCH(1,(成本核算表!D:D=E25)*(成本核算表!C:C=G25),0))} -> 30 | I25: 500 | J25: =H25*I25 -> 15000 | L25: 14400 | N25: =J25-M25+L25 -> 29400 | O25: =N25/3600 -> 8.1666667 | Q25: 挑料4H
A26: 46098 | D26: 26022504-04 | E26: 213-553 | F26: 1960 | G26: 切割45° | H26: {=INDEX(成本核算表!J:J,MATCH(1,(成本核算表!D:D=E26)*(成本核算表!C:C=G26),0))} -> 30 | I26: 320 | J26: =H26*I26 -> 9600 | N26: =J26-M26+L26 -> 9600 | O26: =N26/3600 -> 2.6666667
A27: 46099 | B27: 12 | C27: =SUM(O27:O28)/B27 -> 0.58680556 | D27: 26022504-02 | E27: 213-553 | F27: 780 | G27: 切割45° | H27: {=INDEX(成本核算表!J:J,MATCH(1,(成本核算表!D:D=E27)*(成本核算表!C:C=G27),0))} -> 30 | I27: 505 | J27: =H27*I27 -> 15150 | L27: 7200 | N27: =J27-M27+L27 -> 22350 | O27: =N27/3600 -> 6.2083333
A28: 46099 | D28: 26020502-03 | E28: 105-331 | F28: 119.5 | G28: 沉孔 | H28: {=INDEX(成本核算表!J:J,MATCH(1,(成本核算表!D:D=E28)*(成本核算表!C:C=G28),0))} -> 12 | I28: 250 | J28: =H28*I28 -> 3000 | N28: =J28-M28+L28 -> 3000 | O28: =N28/3600 -> 0.83333333
A29: 46100 | B29: 12 | C29: =SUM(O29:O30)/B29 -> 1.0185185 | D29: 26020502-01 | E29: 105-330 | F29: 260 | G29: CNC1 | H29: {=INDEX(成本核算表!J:J,MATCH(1,(成本核算表!D:D=E29)*(成本核算表!C:C=G29),0))} -> 50 | I29: 400 | J29: =H29*I29 -> 20000 | N29: =J29-M29+L29 -> 20000 | O29: =N29/3600 -> 5.5555556
A30: 46100 | D30: 26020502-01 | E30: 105-330 | F30: 260 | G30: CNC2 | H30: {=INDEX(成本核算表!J:J,MATCH(1,(成本核算表!D:D=E30)*(成本核算表!C:C=G30),0))} -> 60 | I30: 400 | J30: =H30*I30 -> 24000 | N30: =J30-M30+L30 -> 24000 | O30: =N30/3600 -> 6.6666667
A31: 46101 | B31: 12 | C31: =SUM(O31)/B31 -> 0.99259259 | D31: 26031205-01 | E31: 196-110*1447 | F31: 1447 | G31: CNC | H31: {=INDEX(成本核算表!J:J,MATCH(1,(成本核算表!D:D=E31)*(成本核算表!C:C=G31),0))} -> 335 | I31: 130 | J31: =H31*I31 -> 43550 | K31: 2 | M31: =K31*H31 -> 670 | N31: =J31-M31+L31 -> 42880 | O31: =N31/3600 -> 11.911111
H32: {=INDEX(成本核算表!J:J,MATCH(1,(成本核算表!D:D=E32)*(成本核算表!C:C=G32),0))} -> 0 | J32: =H32*I32 -> 0 | N32: =J32-M32+L32 -> 0 | O32: =N32/3600 -> 0
H33: {=INDEX(成本核算表!J:J,MATCH(1,(成本核算表!D:D=E33)*(成本核算表!C:C=G33),0))} -> 0 | J33: =H33*I33 -> 0 | N33: =J33-M33+L33 -> 0 | O33: =N33/3600 -> 0
H34: {=INDEX(成本核算表!J:J,MATCH(1,(成本核算表!D:D=E34)*(成本核算表!C:C=G34),0))} -> 0 | J34: =H34*I34 -> 0 | N34: =J34-M34+L34 -> 0 | O34: =N34/3600 -> 0
H35: {=INDEX(成本核算表!J:J,MATCH(1,(成本核算表!D:D=E35)*(成本核算表!C:C=G35),0))} -> 0 | J35: =H35*I35 -> 0 | N35: =J35-M35+L35 -> 0 | O35: =N35/3600 -> 0
H36: {=INDEX(成本核算表!J:J,MATCH(1,(成本核算表!D:D=E36)*(成本核算表!C:C=G36),0))} -> 0 | J36: =H36*I36 -> 0 | N36: =J36-M36+L36 -> 0 | O36: =N36/3600 -> 0
H37: {=INDEX(成本核算表!J:J,MATCH(1,(成本核算表!D:D=E37)*(成本核算表!C:C=G37),0))} -> 0 | J37: =H37*I37 -> 0 | N37: =J37-M37+L37 -> 0 | O37: =N37/3600 -> 0
H38: {=INDEX(成本核算表!J:J,MATCH(1,(成本核算表!D:D=E38)*(成本核算表!C:C=G38),0))} -> 0 | J38: =H38*I38 -> 0 | N38: =J38-M38+L38 -> 0 | O38: =N38/3600 -> 0
H39: {=INDEX(成本核算表!J:J,MATCH(1,(成本核算表!D:D=E39)*(成本核算表!C:C=G39),0))} -> 0 | J39: =H39*I39 -> 0 | N39: =J39-M39+L39 -> 0 | O39: =N39/3600 -> 0
H40: {=INDEX(成本核算表!J:J,MATCH(1,(成本核算表!D:D=E40)*(成本核算表!C:C=G40),0))} -> 0 | J40: =H40*I40 -> 0 | N40: =J40-M40+L40 -> 0 | O40: =N40/3600 -> 0
...

Sheet 张吉成
A1: 日期 | B1: 出勤工时 | C1: 工时效率 | D1: 项目号 | E1: 产品型号 | F1: 长度（mm） | G1: 工序 | H1: 单件标准工时（S/支） | I1: 合格产量（支数） | J1: 合格工时（S） | K1: 个人不良产量（支数） | L1: 加分项 | M1: 减分项 | N1: 考核合计工时（秒） | O1: 合计（小时） | P1: 说明 | Q1: 备注
A2: 46082 | B2: 12 | C2: =O2/B2 -> 1.1851852 | D2: 25070202-15 | E2: 286-473 | F2: 190 | G2: CNC | H2: {=INDEX(成本核算表!J:J,MATCH(1,(成本核算表!D:D=E2)*(成本核算表!C:C=G2),0))} -> 160 | I2: 320 | J2: =H2*I2 -> 51200 | N2: =J2-M2+L2 -> 51200 | O2: =N2/3600 -> 14.222222
A3: 46083 | B3: 12 | C3: =O3/B3 -> 0.93333333 | D3: 26020502-03 | E3: 105-331 | F3: 119.5 | G3: 沉孔 | H3: {=INDEX(成本核算表!J:J,MATCH(1,(成本核算表!D:D=E3)*(成本核算表!C:C=G3),0))} -> 12 | I3: 3360 | J3: =H3*I3 -> 40320 | N3: =J3-M3+L3 -> 40320 | O3: =N3/3600 -> 11.2
A4: 46084 | B4: 12 | C4: =SUM(O4:O7)/B4 -> 1.2541667 | D4: 26020502-02 | E4: 105-331 | F4: 119.5 | G4: 倒角 | H4: {=INDEX(成本核算表!J:J,MATCH(1,(成本核算表!D:D=E4)*(成本核算表!C:C=G4),0))} -> 15 | I4: 1002 | J4: =H4*I4 -> 15030 | N4: =J4-M4+L4 -> 15030 | O4: =N4/3600 -> 4.175
A5: 46084 | D5: 26022610-05 | E5: 213-357 | F5: 1587.5 | G5: CNC | H5: {=INDEX(成本核算表!J:J,MATCH(1,(成本核算表!D:D=E5)*(成本核算表!C:C=G5),0))} -> 25 | I5: 126 | J5: =H5*I5 -> 3150 | N5: =J5-M5+L5 -> 3150 | O5: =N5/3600 -> 0.875
A6: 46084 | D6: 26022505-03 | E6: 258-308 | F6: 180 | G6: CNC1 | H6: {=INDEX(成本核算表!J:J,MATCH(1,(成本核算表!D:D=E6)*(成本核算表!C:C=G6),0))} -> 800 | I6: 17 | J6: =H6*I6 -> 13600 | N6: =J6-M6+L6 -> 13600 | O6: =N6/3600 -> 3.7777778
A7: 46084 | D7: 26022505-02 | E7: 258-308 | F7: 180 | G7: CNC1 | H7: {=INDEX(成本核算表!J:J,MATCH(1,(成本核算表!D:D=E7)*(成本核算表!C:C=G7),0))} -> 800 | I7: 28 | J7: =H7*I7 -> 22400 | N7: =J7-M7+L7 -> 22400 | O7: =N7/3600 -> 6.2222222
A8: 46085 | B8: 12 | C8: =SUM(O8:O9)/B8 -> 0.95740741 | D8: 25062804-02 | E8: 113-54 | F8: 138.8 | G8: CNC | H8: {=INDEX(成本核算表!J:J,MATCH(1,(成本核算表!D:D=E8)*(成本核算表!C:C=G8),0))} -> 160 | I8: =726/3 -> 242 | J8: =H8*I8 -> 38720 | N8: =J8-M8+L8 -> 38720 | O8: =N8/3600 -> 10.755556
A9: 46085 | E9: 03-10 | F9: 2115 | G9: CNC | H9: {=INDEX(成本核算表!J:J,MATCH(1,(成本核算表!D:D=E9)*(成本核算表!C:C=G9),0))} -> 120 | I9: 22 | J9: =H9*I9 -> 2640 | N9: =J9-M9+L9 -> 2640 | O9: =N9/3600 -> 0.73333333
A11: 46087 | B11: 12 | C11: =O11/B11 -> 1.1805556 | D11: 26020502-02 | E11: 105-331 | F11: 119.5 | G11: 倒角 | H11: {=INDEX(成本核算表!J:J,MATCH(1,(成本核算表!D:D=E11)*(成本核算表!C:C=G11),0))} -> 15 | I11: 3400 | J11: =H11*I11 -> 51000 | N11: =J11-M11+L11 -> 51000 | O11: =N11/3600 -> 14.166667
A12: 46088 | B12: 12 | C12: =O12/B12 -> 0.69777778 | D12: 26020502-03 | E12: 105-331 | F12: 119.5 | G12: 沉孔 | H12: {=INDEX(成本核算表!J:J,MATCH(1,(成本核算表!D:D=E12)*(成本核算表!C:C=G12),0))} -> 12 | I12: 2516 | J12: =H12*I12 -> 30192 | K12: 4 | M12: =K12*H12 -> 48 | N12: =J12-M12+L12 -> 30144 | O12: =N12/3600 -> 8.3733333
H13: {=INDEX(成本核算表!J:J,MATCH(1,(成本核算表!D:D=E13)*(成本核算表!C:C=G13),0))} -> 0 | J13: =H13*I13 -> 0 | M13: =K13*H13 -> 0 | N13: =J13-M13+L13 -> 0 | O13: =N13/3600 -> 0
A14: 46090 | B14: 11 | C14: =SUM(O14)/B14 -> 1.1363636 | D14: 26030101-02 | E14: 196-114 | F14: 2296.8 | G14: CNC | H14: {=INDEX(成本核算表!J:J,MATCH(1,(成本核算表!D:D=E14)*(成本核算表!C:C=G14),0))} -> 600 | I14: 75 | J14: =H14*I14 -> 45000 | M14: =K14*H14 -> 0 | N14: =J14-M14+L14 -> 45000 | O14: =N14/3600 -> 12.5
A15: 46091 | B15: 11 | C15: =SUM(O15)/B15 -> 1.1363636 | D15: 26030101-02 | E15: 196-114 | F15: 2296.8 | G15: CNC | H15: {=INDEX(成本核算表!J:J,MATCH(1,(成本核算表!D:D=E15)*(成本核算表!C:C=G15),0))} -> 600 | I15: 75 | J15: =H15*I15 -> 45000 | M15: =K15*H15 -> 0 | N15: =J15-M15+L15 -> 45000 | O15: =N15/3600 -> 12.5
A16: 46092 | B16: 11 | C16: =SUM(O16)/B16 -> 1.1363636 | D16: 26030101-02 | E16: 196-114 | F16: 2296.8 | G16: CNC | H16: {=INDEX(成本核算表!J:J,MATCH(1,(成本核算表!D:D=E16)*(成本核算表!C:C=G16),0))} -> 600 | I16: 75 | J16: =H16*I16 -> 45000 | M16: =K16*H16 -> 0 | N16: =J16-M16+L16 -> 45000 | O16: =N16/3600 -> 12.5
